Workbook

Sheet Instrucciones jornadas
A1: GESTIÓN DE JORNADAS · CÁDIZ C.F. CADETE FEMENINO 2026/2027
A5: 1 | B5: Abra la pestaña de la jornada correspondiente.
A6: 2 | B6: Seleccione TITULAR, SUPLENTE, RESERVA o NO CONVOCADA.
A7: 3 | B7: Introduzca los minutos de cada parte.
A8: 4 | B8: Registre tarjetas, lesiones e incidencias.
A9: 5 | B9: Registre cada gol solamente en el bloque de goles de esa jornada.

Sheet Seguimiento partidos
A1: SEGUIMIENTO ACUMULADO DE PARTICIPACIÓN
A5: DORSAL | B5: JUGADORA | C5: POSICIÓN | D5: CONVOC. | E5: TITULAR | F5: SUPLENTE | G5: MINUTOS | H5: GOLES | I5: ASIST. | J5: TA | K5: TR | L5: LESIONES | M5: GOLES RECIBIDOS
A6: 1 | B6: Julia | C6: PORTERA | D6: =SUM(--(J01_IDA!D10<>"NO CONVOCADA")*--(J01_IDA!D10<>""),--(J02_IDA!D10<>"NO CONVOCADA")*--(J02_IDA!D10<>""),--(J03_IDA!D10<>"NO CONVOCADA")*--(J03_IDA!D10<>""),--(J04_IDA!D10<>"NO CONVOCADA")*--(J04_IDA!D10<>""),--(J05_IDA!D10<>"NO CONVOCADA")*--(J05_IDA!D10<>""),--(J06_IDA!D10<>"NO CONVOCADA")*--(J06_IDA!D10<>""),--(J07_IDA!D10<>"NO CONVOCADA")*--(J07_IDA!D10<>""),--(J08_IDA!D10<>"NO CONVOCADA")*--(J08_IDA!D10<>""),--(J09_IDA!D10<>"NO CONVOCADA")*--(J09_IDA!D10<>""),--(J10_IDA!D10<>"NO CONVOCADA")*--(J10_IDA!D10<>""),--(J11_IDA!D10<>"NO CONVOCADA")*--(J11_IDA!D10<>""),--(J12_IDA!D10<>"NO CONVOCADA")*--(J12_IDA!D10<>""),--(J13_IDA!D10<>"NO CONVOCADA")*--(J13_IDA!D10<>""),--(J01_VTA!D10<>"NO CONVOCADA")*--(J01_VTA!D10<>""),--(J02_VTA!D10<>"NO CONVOCADA")*--(J02_VTA!D10<>""),--(J03_VTA!D10<>"NO CONVOCADA")*--(J03_VTA!D10<>""),--(J04_VTA!D10<>"NO CONVOCADA")*--(J04_VTA!D10<>""),--(J05_VTA!D10<>"NO CONVOCADA")*--(J05_VTA!D10<>""),--(J06_VTA!D10<>"NO CONVOCADA")*--(J06_VTA!D10<>""),--(J07_VTA!D10<>"NO CONVOCADA")*--(J07_VTA!D10<>""),--(J08_VTA!D10<>"NO CONVOCADA")*--(J08_VTA!D10<>""),--(J09_VTA!D10<>"NO CONVOCADA")*--(J09_VTA!D10<>""),--(J10_VTA!D10<>"NO CONVOCADA")*--(J10_VTA!D10<>""),--(J11_VTA!D10<>"NO CONVOCADA")*--(J11_VTA!D10<>""),--(J12_VTA!D10<>"NO CONVOCADA")*--(J12_VTA!D10<>""),--(J13_VTA!D10<>"NO CONVOCADA")*--(J13_VTA!D10<>"")) -> 1 | E6: =SUM(--(J01_IDA!D10="TITULAR"),--(J02_IDA!D10="TITULAR"),--(J03_IDA!D10="TITULAR"),--(J04_IDA!D10="TITULAR"),--(J05_IDA!D10="TITULAR"),--(J06_IDA!D10="TITULAR"),--(J07_IDA!D10="TITULAR"),--(J08_IDA!D10="TITULAR"),--(J09_IDA!D10="TITULAR"),--(J10_IDA!D10="TITULAR"),--(J11_IDA!D10="TITULAR"),--(J12_IDA!D10="TITULAR"),--(J13_IDA!D10="TITULAR"),--(J01_VTA!D10="TITULAR"),--(J02_VTA!D10="TITULAR"),--(J03_VTA!D10="TITULAR"),--(J04_VTA!D10="TITULAR"),--(J05_VTA!D10="TITULAR"),--(J06_VTA!D10="TITULAR"),--(J07_VTA!D10="TITULAR"),--(J08_VTA!D10="TITULAR"),--(J09_VTA!D10="TITULAR"),--(J10_VTA!D10="TITULAR"),--(J11_VTA!D10="TITULAR"),--(J12_VTA!D10="TITULAR"),--(J13_VTA!D10="TITULAR")) -> 1 | F6: =SUM(--(J01_IDA!D10="SUPLENTE"),--(J02_IDA!D10="SUPLENTE"),--(J03_IDA!D10="SUPLENTE"),--(J04_IDA!D10="SUPLENTE"),--(J05_IDA!D10="SUPLENTE"),--(J06_IDA!D10="SUPLENTE"),--(J07_IDA!D10="SUPLENTE"),--(J08_IDA!D10="SUPLENTE"),--(J09_IDA!D10="SUPLENTE"),--(J10_IDA!D10="SUPLENTE"),--(J11_IDA!D10="SUPLENTE"),--(J12_IDA!D10="SUPLENTE"),--(J13_IDA!D10="SUPLENTE"),--(J01_VTA!D10="SUPLENTE"),--(J02_VTA!D10="SUPLENTE"),--(J03_VTA!D10="SUPLENTE"),--(J04_VTA!D10="SUPLENTE"),--(J05_VTA!D10="SUPLENTE"),--(J06_VTA!D10="SUPLENTE"),--(J07_VTA!D10="SUPLENTE"),--(J08_VTA!D10="SUPLENTE"),--(J09_VTA!D10="SUPLENTE"),--(J10_VTA!D10="SUPLENTE"),--(J11_VTA!D10="SUPLENTE"),--(J12_VTA!D10="SUPLENTE"),--(J13_VTA!D10="SUPLENTE")) -> 0 | G6: =SUM(J01_IDA!G10,J02_IDA!G10,J03_IDA!G10,J04_IDA!G10,J05_IDA!G10,J06_IDA!G10,J07_IDA!G10,J08_IDA!G10,J09_IDA!G10,J10_IDA!G10,J11_IDA!G10,J12_IDA!G10,J13_IDA!G10,J01_VTA!G10,J02_VTA!G10,J03_VTA!G10,J04_VTA!G10,J05_VTA!G10,J06_VTA!G10,J07_VTA!G10,J08_VTA!G10,J09_VTA!G10,J10_VTA!G10,J11_VTA!G10,J12_VTA!G10,J13_VTA!G10) -> 45 | H6: =SUM(J01_IDA!H10,J02_IDA!H10,J03_IDA!H10,J04_IDA!H10,J05_IDA!H10,J06_IDA!H10,J07_IDA!H10,J08_IDA!H10,J09_IDA!H10,J10_IDA!H10,J11_IDA!H10,J12_IDA!H10,J13_IDA!H10,J01_VTA!H10,J02_VTA!H10,J03_VTA!H10,J04_VTA!H10,J05_VTA!H10,J06_VTA!H10,J07_VTA!H10,J08_VTA!H10,J09_VTA!H10,J10_VTA!H10,J11_VTA!H10,J12_VTA!H10,J13_VTA!H10) -> 0 | I6: =SUM(J01_IDA!J10,J02_IDA!J10,J03_IDA!J10,J04_IDA!J10,J05_IDA!J10,J06_IDA!J10,J07_IDA!J10,J08_IDA!J10,J09_IDA!J10,J10_IDA!J10,J11_IDA!J10,J12_IDA!J10,J13_IDA!J10,J01_VTA!J10,J02_VTA!J10,J03_VTA!J10,J04_VTA!J10,J05_VTA!J10,J06_VTA!J10,J07_VTA!J10,J08_VTA!J10,J09_VTA!J10,J10_VTA!J10,J11_VTA!J10,J12_VTA!J10,J13_VTA!J10) -> 0 | J6: =SUM(J01_IDA!K10,J02_IDA!K10,J03_IDA!K10,J04_IDA!K10,J05_IDA!K10,J06_IDA!K10,J07_IDA!K10,J08_IDA!K10,J09_IDA!K10,J10_IDA!K10,J11_IDA!K10,J12_IDA!K10,J13_IDA!K10,J01_VTA!K10,J02_VTA!K10,J03_VTA!K10,J04_VTA!K10,J05_VTA!K10,J06_VTA!K10,J07_VTA!K10,J08_VTA!K10,J09_VTA!K10,J10_VTA!K10,J11_VTA!K10,J12_VTA!K10,J13_VTA!K10) -> 0 | K6: =SUM(J01_IDA!L10,J02_IDA!L10,J03_IDA!L10,J04_IDA!L10,J05_IDA!L10,J06_IDA!L10,J07_IDA!L10,J08_IDA!L10,J09_IDA!L10,J10_IDA!L10,J11_IDA!L10,J12_IDA!L10,J13_IDA!L10,J01_VTA!L10,J02_VTA!L10,J03_VTA!L10,J04_VTA!L10,J05_VTA!L10,J06_VTA!L10,J07_VTA!L10,J08_VTA!L10,J09_VTA!L10,J10_VTA!L10,J11_VTA!L10,J12_VTA!L10,J13_VTA!L10) -> 0 | L6: =SUM(--(J01_IDA!M10="SÍ"),--(J02_IDA!M10="SÍ"),--(J03_IDA!M10="SÍ"),--(J04_IDA!M10="SÍ"),--(J05_IDA!M10="SÍ"),--(J06_IDA!M10="SÍ"),--(J07_IDA!M10="SÍ"),--(J08_IDA!M10="SÍ"),--(J09_IDA!M10="SÍ"),--(J10_IDA!M10="SÍ"),--(J11_IDA!M10="SÍ"),--(J12_IDA!M10="SÍ"),--(J13_IDA!M10="SÍ"),--(J01_VTA!M10="SÍ"),--(J02_VTA!M10="SÍ"),--(J03_VTA!M10="SÍ"),--(J04_VTA!M10="SÍ"),--(J05_VTA!M10="SÍ"),--(J06_VTA!M10="SÍ"),--(J07_VTA!M10="SÍ"),--(J08_VTA!M10="SÍ"),--(J09_VTA!M10="SÍ"),--(J10_VTA!M10="SÍ"),--(J11_VTA!M10="SÍ"),--(J12_VTA!M10="SÍ"),--(J13_VTA!M10="SÍ")) -> 0 | M6: =SUM(J01_IDA!I10,J02_IDA!I10,J03_IDA!I10,J04_IDA!I10,J05_IDA!I10,J06_IDA!I10,J07_IDA!I10,J08_IDA!I10,J09_IDA!I10,J10_IDA!I10,J11_IDA!I10,J12_IDA!I10,J13_IDA!I10,J01_VTA!I10,J02_VTA!I10,J03_VTA!I10,J04_VTA!I10,J05_VTA!I10,J06_VTA!I10,J07_VTA!I10,J08_VTA!I10,J09_VTA!I10,J10_VTA!I10,J11_VTA!I10,J12_VTA!I10,J13_VTA!I10) -> 0
A7: 2 | B7: Alba | C7: L.D. | D7: =SUM(--(J01_IDA!D11<>"NO CONVOCADA")*--(J01_IDA!D11<>""),--(J02_IDA!D11<>"NO CONVOCADA")*--(J02_IDA!D11<>""),--(J03_IDA!D11<>"NO CONVOCADA")*--(J03_IDA!D11<>""),--(J04_IDA!D11<>"NO CONVOCADA")*--(J04_IDA!D11<>""),--(J05_IDA!D11<>"NO CONVOCADA")*--(J05_IDA!D11<>""),--(J06_IDA!D11<>"NO CONVOCADA")*--(J06_IDA!D11<>""),--(J07_IDA!D11<>"NO CONVOCADA")*--(J07_IDA!D11<>""),--(J08_IDA!D11<>"NO CONVOCADA")*--(J08_IDA!D11<>""),--(J09_IDA!D11<>"NO CONVOCADA")*--(J09_IDA!D11<>""),--(J10_IDA!D11<>"NO CONVOCADA")*--(J10_IDA!D11<>""),--(J11_IDA!D11<>"NO CONVOCADA")*--(J11_IDA!D11<>""),--(J12_IDA!D11<>"NO CONVOCADA")*--(J12_IDA!D11<>""),--(J13_IDA!D11<>"NO CONVOCADA")*--(J13_IDA!D11<>""),--(J01_VTA!D11<>"NO CONVOCADA")*--(J01_VTA!D11<>""),--(J02_VTA!D11<>"NO CONVOCADA")*--(J02_VTA!D11<>""),--(J03_VTA!D11<>"NO CONVOCADA")*--(J03_VTA!D11<>""),--(J04_VTA!D11<>"NO CONVOCADA")*--(J04_VTA!D11<>""),--(J05_VTA!D11<>"NO CONVOCADA")*--(J05_VTA!D11<>""),--(J06_VTA!D11<>"NO CONVOCADA")*--(J06_VTA!D11<>""),--(J07_VTA!D11<>"NO CONVOCADA")*--(J07_VTA!D11<>""),--(J08_VTA!D11<>"NO CONVOCADA")*--(J08_VTA!D11<>""),--(J09_VTA!D11<>"NO CONVOCADA")*--(J09_VTA!D11<>""),--(J10_VTA!D11<>"NO CONVOCADA")*--(J10_VTA!D11<>""),--(J11_VTA!D11<>"NO CONVOCADA")*--(J11_VTA!D11<>""),--(J12_VTA!D11<>"NO CONVOCADA")*--(J12_VTA!D11<>""),--(J13_VTA!D11<>"NO CONVOCADA")*--(J13_VTA!D11<>"")) -> 1 | E7: =SUM(--(J01_IDA!D11="TITULAR"),--(J02_IDA!D11="TITULAR"),--(J03_IDA!D11="TITULAR"),--(J04_IDA!D11="TITULAR"),--(J05_IDA!D11="TITULAR"),--(J06_IDA!D11="TITULAR"),--(J07_IDA!D11="TITULAR"),--(J08_IDA!D11="TITULAR"),--(J09_IDA!D11="TITULAR"),--(J10_IDA!D11="TITULAR"),--(J11_IDA!D11="TITULAR"),--(J12_IDA!D11="TITULAR"),--(J13_IDA!D11="TITULAR"),--(J01_VTA!D11="TITULAR"),--(J02_VTA!D11="TITULAR"),--(J03_VTA!D11="TITULAR"),--(J04_VTA!D11="TITULAR"),--(J05_VTA!D11="TITULAR"),--(J06_VTA!D11="TITULAR"),--(J07_VTA!D11="TITULAR"),--(J08_VTA!D11="TITULAR"),--(J09_VTA!D11="TITULAR"),--(J10_VTA!D11="TITULAR"),--(J11_VTA!D11="TITULAR"),--(J12_VTA!D11="TITULAR"),--(J13_VTA!D11="TITULAR")) -> 1 | F7: =SUM(--(J01_IDA!D11="SUPLENTE"),--(J02_IDA!D11="SUPLENTE"),--(J03_IDA!D11="SUPLENTE"),--(J04_IDA!D11="SUPLENTE"),--(J05_IDA!D11="SUPLENTE"),--(J06_IDA!D11="SUPLENTE"),--(J07_IDA!D11="SUPLENTE"),--(J08_IDA!D11="SUPLENTE"),--(J09_IDA!D11="SUPLENTE"),--(J10_IDA!D11="SUPLENTE"),--(J11_IDA!D11="SUPLENTE"),--(J12_IDA!D11="SUPLENTE"),--(J13_IDA!D11="SUPLENTE"),--(J01_VTA!D11="SUPLENTE"),--(J02_VTA!D11="SUPLENTE"),--(J03_VTA!D11="SUPLENTE"),--(J04_VTA!D11="SUPLENTE"),--(J05_VTA!D11="SUPLENTE"),--(J06_VTA!D11="SUPLENTE"),--(J07_VTA!D11="SUPLENTE"),--(J08_VTA!D11="SUPLENTE"),--(J09_VTA!D11="SUPLENTE"),--(J10_VTA!D11="SUPLENTE"),--(J11_VTA!D11="SUPLENTE"),--(J12_VTA!D11="SUPLENTE"),--(J13_VTA!D11="SUPLENTE")) -> 0 | G7: =SUM(J01_IDA!G11,J02_IDA!G11,J03_IDA!G11,J04_IDA!G11,J05_IDA!G11,J06_IDA!G11,J07_IDA!G11,J08_IDA!G11,J09_IDA!G11,J10_IDA!G11,J11_IDA!G11,J12_IDA!G11,J13_IDA!G11,J01_VTA!G11,J02_VTA!G11,J03_VTA!G11,J04_VTA!G11,J05_VTA!G11,J06_VTA!G11,J07_VTA!G11,J08_VTA!G11,J09_VTA!G11,J10_VTA!G11,J11_VTA!G11,J12_VTA!G11,J13_VTA!G11) -> 63 | H7: =SUM(J01_IDA!H11,J02_IDA!H11,J03_IDA!H11,J04_IDA!H11,J05_IDA!H11,J06_IDA!H11,J07_IDA!H11,J08_IDA!H11,J09_IDA!H11,J10_IDA!H11,J11_IDA!H11,J12_IDA!H11,J13_IDA!H11,J01_VTA!H11,J02_VTA!H11,J03_VTA!H11,J04_VTA!H11,J05_VTA!H11,J06_VTA!H11,J07_VTA!H11,J08_VTA!H11,J09_VTA!H11,J10_VTA!H11,J11_VTA!H11,J12_VTA!H11,J13_VTA!H11) -> 0 | I7: =SUM(J01_IDA!J11,J02_IDA!J11,J03_IDA!J11,J04_IDA!J11,J05_IDA!J11,J06_IDA!J11,J07_IDA!J11,J08_IDA!J11,J09_IDA!J11,J10_IDA!J11,J11_IDA!J11,J12_IDA!J11,J13_IDA!J11,J01_VTA!J11,J02_VTA!J11,J03_VTA!J11,J04_VTA!J11,J05_VTA!J11,J06_VTA!J11,J07_VTA!J11,J08_VTA!J11,J09_VTA!J11,J10_VTA!J11,J11_VTA!J11,J12_VTA!J11,J13_VTA!J11) -> 0 | J7: =SUM(J01_IDA!K11,J02_IDA!K11,J03_IDA!K11,J04_IDA!K11,J05_IDA!K11,J06_IDA!K11,J07_IDA!K11,J08_IDA!K11,J09_IDA!K11,J10_IDA!K11,J11_IDA!K11,J12_IDA!K11,J13_IDA!K11,J01_VTA!K11,J02_VTA!K11,J03_VTA!K11,J04_VTA!K11,J05_VTA!K11,J06_VTA!K11,J07_VTA!K11,J08_VTA!K11,J09_VTA!K11,J10_VTA!K11,J11_VTA!K11,J12_VTA!K11,J13_VTA!K11) -> 0 | K7: =SUM(J01_IDA!L11,J02_IDA!L11,J03_IDA!L11,J04_IDA!L11,J05_IDA!L11,J06_IDA!L11,J07_IDA!L11,J08_IDA!L11,J09_IDA!L11,J10_IDA!L11,J11_IDA!L11,J12_IDA!L11,J13_IDA!L11,J01_VTA!L11,J02_VTA!L11,J03_VTA!L11,J04_VTA!L11,J05_VTA!L11,J06_VTA!L11,J07_VTA!L11,J08_VTA!L11,J09_VTA!L11,J10_VTA!L11,J11_VTA!L11,J12_VTA!L11,J13_VTA!L11) -> 0 | L7: =SUM(--(J01_IDA!M11="SÍ"),--(J02_IDA!M11="SÍ"),--(J03_IDA!M11="SÍ"),--(J04_IDA!M11="SÍ"),--(J05_IDA!M11="SÍ"),--(J06_IDA!M11="SÍ"),--(J07_IDA!M11="SÍ"),--(J08_IDA!M11="SÍ"),--(J09_IDA!M11="SÍ"),--(J10_IDA!M11="SÍ"),--(J11_IDA!M11="SÍ"),--(J12_IDA!M11="SÍ"),--(J13_IDA!M11="SÍ"),--(J01_VTA!M11="SÍ"),--(J02_VTA!M11="SÍ"),--(J03_VTA!M11="SÍ"),--(J04_VTA!M11="SÍ"),--(J05_VTA!M11="SÍ"),--(J06_VTA!M11="SÍ"),--(J07_VTA!M11="SÍ"),--(J08_VTA!M11="SÍ"),--(J09_VTA!M11="SÍ"),--(J10_VTA!M11="SÍ"),--(J11_VTA!M11="SÍ"),--(J12_VTA!M11="SÍ"),--(J13_VTA!M11="SÍ")) -> 0 | M7: =SUM(J01_IDA!I11,J02_IDA!I11,J03_IDA!I11,J04_IDA!I11,J05_IDA!I11,J06_IDA!I11,J07_IDA!I11,J08_IDA!I11,J09_IDA!I11,J10_IDA!I11,J11_IDA!I11,J12_IDA!I11,J13_IDA!I11,J01_VTA!I11,J02_VTA!I11,J03_VTA!I11,J04_VTA!I11,J05_VTA!I11,J06_VTA!I11,J07_VTA!I11,J08_VTA!I11,J09_VTA!I11,J10_VTA!I11,J11_VTA!I11,J12_VTA!I11,J13_VTA!I11) -> 0
A8: 3 | B8: Margarita | C8: L.I. | D8: =SUM(--(J01_IDA!D12<>"NO CONVOCADA")*--(J01_IDA!D12<>""),--(J02_IDA!D12<>"NO CONVOCADA")*--(J02_IDA!D12<>""),--(J03_IDA!D12<>"NO CONVOCADA")*--(J03_IDA!D12<>""),--(J04_IDA!D12<>"NO CONVOCADA")*--(J04_IDA!D12<>""),--(J05_IDA!D12<>"NO CONVOCADA")*--(J05_IDA!D12<>""),--(J06_IDA!D12<>"NO CONVOCADA")*--(J06_IDA!D12<>""),--(J07_IDA!D12<>"NO CONVOCADA")*--(J07_IDA!D12<>""),--(J08_IDA!D12<>"NO CONVOCADA")*--(J08_IDA!D12<>""),--(J09_IDA!D12<>"NO CONVOCADA")*--(J09_IDA!D12<>""),--(J10_IDA!D12<>"NO CONVOCADA")*--(J10_IDA!D12<>""),--(J11_IDA!D12<>"NO CONVOCADA")*--(J11_IDA!D12<>""),--(J12_IDA!D12<>"NO CONVOCADA")*--(J12_IDA!D12<>""),--(J13_IDA!D12<>"NO CONVOCADA")*--(J13_IDA!D12<>""),--(J01_VTA!D12<>"NO CONVOCADA")*--(J01_VTA!D12<>""),--(J02_VTA!D12<>"NO CONVOCADA")*--(J02_VTA!D12<>""),--(J03_VTA!D12<>"NO CONVOCADA")*--(J03_VTA!D12<>""),--(J04_VTA!D12<>"NO CONVOCADA")*--(J04_VTA!D12<>""),--(J05_VTA!D12<>"NO CONVOCADA")*--(J05_VTA!D12<>""),--(J06_VTA!D12<>"NO CONVOCADA")*--(J06_VTA!D12<>""),--(J07_VTA!D12<>"NO CONVOCADA")*--(J07_VTA!D12<>""),--(J08_VTA!D12<>"NO CONVOCADA")*--(J08_VTA!D12<>""),--(J09_VTA!D12<>"NO CONVOCADA")*--(J09_VTA!D12<>""),--(J10_VTA!D12<>"NO CONVOCADA")*--(J10_VTA!D12<>""),--(J11_VTA!D12<>"NO CONVOCADA")*--(J11_VTA!D12<>""),--(J12_VTA!D12<>"NO CONVOCADA")*--(J12_VTA!D12<>""),--(J13_VTA!D12<>"NO CONVOCADA")*--(J13_VTA!D12<>"")) -> 1 | E8: =SUM(--(J01_IDA!D12="TITULAR"),--(J02_IDA!D12="TITULAR"),--(J03_IDA!D12="TITULAR"),--(J04_IDA!D12="TITULAR"),--(J05_IDA!D12="TITULAR"),--(J06_IDA!D12="TITULAR"),--(J07_IDA!D12="TITULAR"),--(J08_IDA!D12="TITULAR"),--(J09_IDA!D12="TITULAR"),--(J10_IDA!D12="TITULAR"),--(J11_IDA!D12="TITULAR"),--(J12_IDA!D12="TITULAR"),--(J13_IDA!D12="TITULAR"),--(J01_VTA!D12="TITULAR"),--(J02_VTA!D12="TITULAR"),--(J03_VTA!D12="TITULAR"),--(J04_VTA!D12="TITULAR"),--(J05_VTA!D12="TITULAR"),--(J06_VTA!D12="TITULAR"),--(J07_VTA!D12="TITULAR"),--(J08_VTA!D12="TITULAR"),--(J09_VTA!D12="TITULAR"),--(J10_VTA!D12="TITULAR"),--(J11_VTA!D12="TITULAR"),--(J12_VTA!D12="TITULAR"),--(J13_VTA!D12="TITULAR")) -> 1 | F8: =SUM(--(J01_IDA!D12="SUPLENTE"),--(J02_IDA!D12="SUPLENTE"),--(J03_IDA!D12="SUPLENTE"),--(J04_IDA!D12="SUPLENTE"),--(J05_IDA!D12="SUPLENTE"),--(J06_IDA!D12="SUPLENTE"),--(J07_IDA!D12="SUPLENTE"),--(J08_IDA!D12="SUPLENTE"),--(J09_IDA!D12="SUPLENTE"),--(J10_IDA!D12="SUPLENTE"),--(J11_IDA!D12="SUPLENTE"),--(J12_IDA!D12="SUPLENTE"),--(J13_IDA!D12="SUPLENTE"),--(J01_VTA!D12="SUPLENTE"),--(J02_VTA!D12="SUPLENTE"),--(J03_VTA!D12="SUPLENTE"),--(J04_VTA!D12="SUPLENTE"),--(J05_VTA!D12="SUPLENTE"),--(J06_VTA!D12="SUPLENTE"),--(J07_VTA!D12="SUPLENTE"),--(J08_VTA!D12="SUPLENTE"),--(J09_VTA!D12="SUPLENTE"),--(J10_VTA!D12="SUPLENTE"),--(J11_VTA!D12="SUPLENTE"),--(J12_VTA!D12="SUPLENTE"),--(J13_VTA!D12="SUPLENTE")) -> 0 | G8: =SUM(J01_IDA!G12,J02_IDA!G12,J03_IDA!G12,J04_IDA!G12,J05_IDA!G12,J06_IDA!G12,J07_IDA!G12,J08_IDA!G12,J09_IDA!G12,J10_IDA!G12,J11_IDA!G12,J12_IDA!G12,J13_IDA!G12,J01_VTA!G12,J02_VTA!G12,J03_VTA!G12,J04_VTA!G12,J05_VTA!G12,J06_VTA!G12,J07_VTA!G12,J08_VTA!G12,J09_VTA!G12,J10_VTA!G12,J11_VTA!G12,J12_VTA!G12,J13_VTA!G12) -> 61 | H8: =SUM(J01_IDA!H12,J02_IDA!H12,J03_IDA!H12,J04_IDA!H12,J05_IDA!H12,J06_IDA!H12,J07_IDA!H12,J08_IDA!H12,J09_IDA!H12,J10_IDA!H12,J11_IDA!H12,J12_IDA!H12,J13_IDA!H12,J01_VTA!H12,J02_VTA!H12,J03_VTA!H12,J04_VTA!H12,J05_VTA!H12,J06_VTA!H12,J07_VTA!H12,J08_VTA!H12,J09_VTA!H12,J10_VTA!H12,J11_VTA!H12,J12_VTA!H12,J13_VTA!H12) -> 0 | I8: =SUM(J01_IDA!J12,J02_IDA!J12,J03_IDA!J12,J04_IDA!J12,J05_IDA!J12,J06_IDA!J12,J07_IDA!J12,J08_IDA!J12,J09_IDA!J12,J10_IDA!J12,J11_IDA!J12,J12_IDA!J12,J13_IDA!J12,J01_VTA!J12,J02_VTA!J12,J03_VTA!J12,J04_VTA!J12,J05_VTA!J12,J06_VTA!J12,J07_VTA!J12,J08_VTA!J12,J09_VTA!J12,J10_VTA!J12,J11_VTA!J12,J12_VTA!J12,J13_VTA!J12) -> 0 | J8: =SUM(J01_IDA!K12,J02_IDA!K12,J03_IDA!K12,J04_IDA!K12,J05_IDA!K12,J06_IDA!K12,J07_IDA!K12,J08_IDA!K12,J09_IDA!K12,J10_IDA!K12,J11_IDA!K12,J12_IDA!K12,J13_IDA!K12,J01_VTA!K12,J02_VTA!K12,J03_VTA!K12,J04_VTA!K12,J05_VTA!K12,J06_VTA!K12,J07_VTA!K12,J08_VTA!K12,J09_VTA!K12,J10_VTA!K12,J11_VTA!K12,J12_VTA!K12,J13_VTA!K12) -> 0 | K8: =SUM(J01_IDA!L12,J02_IDA!L12,J03_IDA!L12,J04_IDA!L12,J05_IDA!L12,J06_IDA!L12,J07_IDA!L12,J08_IDA!L12,J09_IDA!L12,J10_IDA!L12,J11_IDA!L12,J12_IDA!L12,J13_IDA!L12,J01_VTA!L12,J02_VTA!L12,J03_VTA!L12,J04_VTA!L12,J05_VTA!L12,J06_VTA!L12,J07_VTA!L12,J08_VTA!L12,J09_VTA!L12,J10_VTA!L12,J11_VTA!L12,J12_VTA!L12,J13_VTA!L12) -> 0 | L8: =SUM(--(J01_IDA!M12="SÍ"),--(J02_IDA!M12="SÍ"),--(J03_IDA!M12="SÍ"),--(J04_IDA!M12="SÍ"),--(J05_IDA!M12="SÍ"),--(J06_IDA!M12="SÍ"),--(J07_IDA!M12="SÍ"),--(J08_IDA!M12="SÍ"),--(J09_IDA!M12="SÍ"),--(J10_IDA!M12="SÍ"),--(J11_IDA!M12="SÍ"),--(J12_IDA!M12="SÍ"),--(J13_IDA!M12="SÍ"),--(J01_VTA!M12="SÍ"),--(J02_VTA!M12="SÍ"),--(J03_VTA!M12="SÍ"),--(J04_VTA!M12="SÍ"),--(J05_VTA!M12="SÍ"),--(J06_VTA!M12="SÍ"),--(J07_VTA!M12="SÍ"),--(J08_VTA!M12="SÍ"),--(J09_VTA!M12="SÍ"),--(J10_VTA!M12="SÍ"),--(J11_VTA!M12="SÍ"),--(J12_VTA!M12="SÍ"),--(J13_VTA!M12="SÍ")) -> 0 | M8: =SUM(J01_IDA!I12,J02_IDA!I12,J03_IDA!I12,J04_IDA!I12,J05_IDA!I12,J06_IDA!I12,J07_IDA!I12,J08_IDA!I12,J09_IDA!I12,J10_IDA!I12,J11_IDA!I12,J12_IDA!I12,J13_IDA!I12,J01_VTA!I12,J02_VTA!I12,J03_VTA!I12,J04_VTA!I12,J05_VTA!I12,J06_VTA!I12,J07_VTA!I12,J08_VTA!I12,J09_VTA!I12,J10_VTA!I12,J11_VTA!I12,J12_VTA!I12,J13_VTA!I12) -> 0
A9: 4 | B9: Valentina | C9: CENTRAL / M.C. | D9: =SUM(--(J01_IDA!D13<>"NO CONVOCADA")*--(J01_IDA!D13<>""),--(J02_IDA!D13<>"NO CONVOCADA")*--(J02_IDA!D13<>""),--(J03_IDA!D13<>"NO CONVOCADA")*--(J03_IDA!D13<>""),--(J04_IDA!D13<>"NO CONVOCADA")*--(J04_IDA!D13<>""),--(J05_IDA!D13<>"NO CONVOCADA")*--(J05_IDA!D13<>""),--(J06_IDA!D13<>"NO CONVOCADA")*--(J06_IDA!D13<>""),--(J07_IDA!D13<>"NO CONVOCADA")*--(J07_IDA!D13<>""),--(J08_IDA!D13<>"NO CONVOCADA")*--(J08_IDA!D13<>""),--(J09_IDA!D13<>"NO CONVOCADA")*--(J09_IDA!D13<>""),--(J10_IDA!D13<>"NO CONVOCADA")*--(J10_IDA!D13<>""),--(J11_IDA!D13<>"NO CONVOCADA")*--(J11_IDA!D13<>""),--(J12_IDA!D13<>"NO CONVOCADA")*--(J12_IDA!D13<>""),--(J13_IDA!D13<>"NO CONVOCADA")*--(J13_IDA!D13<>""),--(J01_VTA!D13<>"NO CONVOCADA")*--(J01_VTA!D13<>""),--(J02_VTA!D13<>"NO CONVOCADA")*--(J02_VTA!D13<>""),--(J03_VTA!D13<>"NO CONVOCADA")*--(J03_VTA!D13<>""),--(J04_VTA!D13<>"NO CONVOCADA")*--(J04_VTA!D13<>""),--(J05_VTA!D13<>"NO CONVOCADA")*--(J05_VTA!D13<>""),--(J06_VTA!D13<>"NO CONVOCADA")*--(J06_VTA!D13<>""),--(J07_VTA!D13<>"NO CONVOCADA")*--(J07_VTA!D13<>""),--(J08_VTA!D13<>"NO CONVOCADA")*--(J08_VTA!D13<>""),--(J09_VTA!D13<>"NO CONVOCADA")*--(J09_VTA!D13<>""),--(J10_VTA!D13<>"NO CONVOCADA")*--(J10_VTA!D13<>""),--(J11_VTA!D13<>"NO CONVOCADA")*--(J11_VTA!D13<>""),--(J12_VTA!D13<>"NO CONVOCADA")*--(J12_VTA!D13<>""),--(J13_VTA!D13<>"NO CONVOCADA")*--(J13_VTA!D13<>"")) -> 1 | E9: =SUM(--(J01_IDA!D13="TITULAR"),--(J02_IDA!D13="TITULAR"),--(J03_IDA!D13="TITULAR"),--(J04_IDA!D13="TITULAR"),--(J05_IDA!D13="TITULAR"),--(J06_IDA!D13="TITULAR"),--(J07_IDA!D13="TITULAR"),--(J08_IDA!D13="TITULAR"),--(J09_IDA!D13="TITULAR"),--(J10_IDA!D13="TITULAR"),--(J11_IDA!D13="TITULAR"),--(J12_IDA!D13="TITULAR"),--(J13_IDA!D13="TITULAR"),--(J01_VTA!D13="TITULAR"),--(J02_VTA!D13="TITULAR"),--(J03_VTA!D13="TITULAR"),--(J04_VTA!D13="TITULAR"),--(J05_VTA!D13="TITULAR"),--(J06_VTA!D13="TITULAR"),--(J07_VTA!D13="TITULAR"),--(J08_VTA!D13="TITULAR"),--(J09_VTA!D13="TITULAR"),--(J10_VTA!D13="TITULAR"),--(J11_VTA!D13="TITULAR"),--(J12_VTA!D13="TITULAR"),--(J13_VTA!D13="TITULAR")) -> 1 | F9: =SUM(--(J01_IDA!D13="SUPLENTE"),--(J02_IDA!D13="SUPLENTE"),--(J03_IDA!D13="SUPLENTE"),--(J04_IDA!D13="SUPLENTE"),--(J05_IDA!D13="SUPLENTE"),--(J06_IDA!D13="SUPLENTE"),--(J07_IDA!D13="SUPLENTE"),--(J08_IDA!D13="SUPLENTE"),--(J09_IDA!D13="SUPLENTE"),--(J10_IDA!D13="SUPLENTE"),--(J11_IDA!D13="SUPLENTE"),--(J12_IDA!D13="SUPLENTE"),--(J13_IDA!D13="SUPLENTE"),--(J01_VTA!D13="SUPLENTE"),--(J02_VTA!D13="SUPLENTE"),--(J03_VTA!D13="SUPLENTE"),--(J04_VTA!D13="SUPLENTE"),--(J05_VTA!D13="SUPLENTE"),--(J06_VTA!D13="SUPLENTE"),--(J07_VTA!D13="SUPLENTE"),--(J08_VTA!D13="SUPLENTE"),--(J09_VTA!D13="SUPLENTE"),--(J10_VTA!D13="SUPLENTE"),--(J11_VTA!D13="SUPLENTE"),--(J12_VTA!D13="SUPLENTE"),--(J13_VTA!D13="SUPLENTE")) -> 0 | G9: =SUM(J01_IDA!G13,J02_IDA!G13,J03_IDA!G13,J04_IDA!G13,J05_IDA!G13,J06_IDA!G13,J07_IDA!G13,J08_IDA!G13,J09_IDA!G13,J10_IDA!G13,J11_IDA!G13,J12_IDA!G13,J13_IDA!G13,J01_VTA!G13,J02_VTA!G13,J03_VTA!G13,J04_VTA!G13,J05_VTA!G13,J06_VTA!G13,J07_VTA!G13,J08_VTA!G13,J09_VTA!G13,J10_VTA!G13,J11_VTA!G13,J12_VTA!G13,J13_VTA!G13) -> 90 | H9: =SUM(J01_IDA!H13,J02_IDA!H13,J03_IDA!H13,J04_IDA!H13,J05_IDA!H13,J06_IDA!H13,J07_IDA!H13,J08_IDA!H13,J09_IDA!H13,J10_IDA!H13,J11_IDA!H13,J12_IDA!H13,J13_IDA!H13,J01_VTA!H13,J02_VTA!H13,J03_VTA!H13,J04_VTA!H13,J05_VTA!H13,J06_VTA!H13,J07_VTA!H13,J08_VTA!H13,J09_VTA!H13,J10_VTA!H13,J11_VTA!H13,J12_VTA!H13,J13_VTA!H13) -> 0 | I9: =SUM(J01_IDA!J13,J02_IDA!J13,J03_IDA!J13,J04_IDA!J13,J05_IDA!J13,J06_IDA!J13,J07_IDA!J13,J08_IDA!J13,J09_IDA!J13,J10_IDA!J13,J11_IDA!J13,J12_IDA!J13,J13_IDA!J13,J01_VTA!J13,J02_VTA!J13,J03_VTA!J13,J04_VTA!J13,J05_VTA!J13,J06_VTA!J13,J07_VTA!J13,J08_VTA!J13,J09_VTA!J13,J10_VTA!J13,J11_VTA!J13,J12_VTA!J13,J13_VTA!J13) -> 0 | J9: =SUM(J01_IDA!K13,J02_IDA!K13,J03_IDA!K13,J04_IDA!K13,J05_IDA!K13,J06_IDA!K13,J07_IDA!K13,J08_IDA!K13,J09_IDA!K13,J10_IDA!K13,J11_IDA!K13,J12_IDA!K13,J13_IDA!K13,J01_VTA!K13,J02_VTA!K13,J03_VTA!K13,J04_VTA!K13,J05_VTA!K13,J06_VTA!K13,J07_VTA!K13,J08_VTA!K13,J09_VTA!K13,J10_VTA!K13,J11_VTA!K13,J12_VTA!K13,J13_VTA!K13) -> 0 | K9: =SUM(J01_IDA!L13,J02_IDA!L13,J03_IDA!L13,J04_IDA!L13,J05_IDA!L13,J06_IDA!L13,J07_IDA!L13,J08_IDA!L13,J09_IDA!L13,J10_IDA!L13,J11_IDA!L13,J12_IDA!L13,J13_IDA!L13,J01_VTA!L13,J02_VTA!L13,J03_VTA!L13,J04_VTA!L13,J05_VTA!L13,J06_VTA!L13,J07_VTA!L13,J08_VTA!L13,J09_VTA!L13,J10_VTA!L13,J11_VTA!L13,J12_VTA!L13,J13_VTA!L13) -> 0 | L9: =SUM(--(J01_IDA!M13="SÍ"),--(J02_IDA!M13="SÍ"),--(J03_IDA!M13="SÍ"),--(J04_IDA!M13="SÍ"),--(J05_IDA!M13="SÍ"),--(J06_IDA!M13="SÍ"),--(J07_IDA!M13="SÍ"),--(J08_IDA!M13="SÍ"),--(J09_IDA!M13="SÍ"),--(J10_IDA!M13="SÍ"),--(J11_IDA!M13="SÍ"),--(J12_IDA!M13="SÍ"),--(J13_IDA!M13="SÍ"),--(J01_VTA!M13="SÍ"),--(J02_VTA!M13="SÍ"),--(J03_VTA!M13="SÍ"),--(J04_VTA!M13="SÍ"),--(J05_VTA!M13="SÍ"),--(J06_VTA!M13="SÍ"),--(J07_VTA!M13="SÍ"),--(J08_VTA!M13="SÍ"),--(J09_VTA!M13="SÍ"),--(J10_VTA!M13="SÍ"),--(J11_VTA!M13="SÍ"),--(J12_VTA!M13="SÍ"),--(J13_VTA!M13="SÍ")) -> 0 | M9: =SUM(J01_IDA!I13,J02_IDA!I13,J03_IDA!I13,J04_IDA!I13,J05_IDA!I13,J06_IDA!I13,J07_IDA!I13,J08_IDA!I13,J09_IDA!I13,J10_IDA!I13,J11_IDA!I13,J12_IDA!I13,J13_IDA!I13,J01_VTA!I13,J02_VTA!I13,J03_VTA!I13,J04_VTA!I13,J05_VTA!I13,J06_VTA!I13,J07_VTA!I13,J08_VTA!I13,J09_VTA!I13,J10_VTA!I13,J11_VTA!I13,J12_VTA!I13,J13_VTA!I13) -> 0
A10: 5 | B10: Ainhoa | C10: CENTRAL | D10: =SUM(--(J01_IDA!D14<>"NO CONVOCADA")*--(J01_IDA!D14<>""),--(J02_IDA!D14<>"NO CONVOCADA")*--(J02_IDA!D14<>""),--(J03_IDA!D14<>"NO CONVOCADA")*--(J03_IDA!D14<>""),--(J04_IDA!D14<>"NO CONVOCADA")*--(J04_IDA!D14<>""),--(J05_IDA!D14<>"NO CONVOCADA")*--(J05_IDA!D14<>""),--(J06_IDA!D14<>"NO CONVOCADA")*--(J06_IDA!D14<>""),--(J07_IDA!D14<>"NO CONVOCADA")*--(J07_IDA!D14<>""),--(J08_IDA!D14<>"NO CONVOCADA")*--(J08_IDA!D14<>""),--(J09_IDA!D14<>"NO CONVOCADA")*--(J09_IDA!D14<>""),--(J10_IDA!D14<>"NO CONVOCADA")*--(J10_IDA!D14<>""),--(J11_IDA!D14<>"NO CONVOCADA")*--(J11_IDA!D14<>""),--(J12_IDA!D14<>"NO CONVOCADA")*--(J12_IDA!D14<>""),--(J13_IDA!D14<>"NO CONVOCADA")*--(J13_IDA!D14<>""),--(J01_VTA!D14<>"NO CONVOCADA")*--(J01_VTA!D14<>""),--(J02_VTA!D14<>"NO CONVOCADA")*--(J02_VTA!D14<>""),--(J03_VTA!D14<>"NO CONVOCADA")*--(J03_VTA!D14<>""),--(J04_VTA!D14<>"NO CONVOCADA")*--(J04_VTA!D14<>""),--(J05_VTA!D14<>"NO CONVOCADA")*--(J05_VTA!D14<>""),--(J06_VTA!D14<>"NO CONVOCADA")*--(J06_VTA!D14<>""),--(J07_VTA!D14<>"NO CONVOCADA")*--(J07_VTA!D14<>""),--(J08_VTA!D14<>"NO CONVOCADA")*--(J08_VTA!D14<>""),--(J09_VTA!D14<>"NO CONVOCADA")*--(J09_VTA!D14<>""),--(J10_VTA!D14<>"NO CONVOCADA")*--(J10_VTA!D14<>""),--(J11_VTA!D14<>"NO CONVOCADA")*--(J11_VTA!D14<>""),--(J12_VTA!D14<>"NO CONVOCADA")*--(J12_VTA!D14<>""),--(J13_VTA!D14<>"NO CONVOCADA")*--(J13_VTA!D14<>"")) -> 1 | E10: =SUM(--(J01_IDA!D14="TITULAR"),--(J02_IDA!D14="TITULAR"),--(J03_IDA!D14="TITULAR"),--(J04_IDA!D14="TITULAR"),--(J05_IDA!D14="TITULAR"),--(J06_IDA!D14="TITULAR"),--(J07_IDA!D14="TITULAR"),--(J08_IDA!D14="TITULAR"),--(J09_IDA!D14="TITULAR"),--(J10_IDA!D14="TITULAR"),--(J11_IDA!D14="TITULAR"),--(J12_IDA!D14="TITULAR"),--(J13_IDA!D14="TITULAR"),--(J01_VTA!D14="TITULAR"),--(J02_VTA!D14="TITULAR"),--(J03_VTA!D14="TITULAR"),--(J04_VTA!D14="TITULAR"),--(J05_VTA!D14="TITULAR"),--(J06_VTA!D14="TITULAR"),--(J07_VTA!D14="TITULAR"),--(J08_VTA!D14="TITULAR"),--(J09_VTA!D14="TITULAR"),--(J10_VTA!D14="TITULAR"),--(J11_VTA!D14="TITULAR"),--(J12_VTA!D14="TITULAR"),--(J13_VTA!D14="TITULAR")) -> 1 | F10: =SUM(--(J01_IDA!D14="SUPLENTE"),--(J02_IDA!D14="SUPLENTE"),--(J03_IDA!D14="SUPLENTE"),--(J04_IDA!D14="SUPLENTE"),--(J05_IDA!D14="SUPLENTE"),--(J06_IDA!D14="SUPLENTE"),--(J07_IDA!D14="SUPLENTE"),--(J08_IDA!D14="SUPLENTE"),--(J09_IDA!D14="SUPLENTE"),--(J10_IDA!D14="SUPLENTE"),--(J11_IDA!D14="SUPLENTE"),--(J12_IDA!D14="SUPLENTE"),--(J13_IDA!D14="SUPLENTE"),--(J01_VTA!D14="SUPLENTE"),--(J02_VTA!D14="SUPLENTE"),--(J03_VTA!D14="SUPLENTE"),--(J04_VTA!D14="SUPLENTE"),--(J05_VTA!D14="SUPLENTE"),--(J06_VTA!D14="SUPLENTE"),--(J07_VTA!D14="SUPLENTE"),--(J08_VTA!D14="SUPLENTE"),--(J09_VTA!D14="SUPLENTE"),--(J10_VTA!D14="SUPLENTE"),--(J11_VTA!D14="SUPLENTE"),--(J12_VTA!D14="SUPLENTE"),--(J13_VTA!D14="SUPLENTE")) -> 0 | G10: =SUM(J01_IDA!G14,J02_IDA!G14,J03_IDA!G14,J04_IDA!G14,J05_IDA!G14,J06_IDA!G14,J07_IDA!G14,J08_IDA!G14,J09_IDA!G14,J10_IDA!G14,J11_IDA!G14,J12_IDA!G14,J13_IDA!G14,J01_VTA!G14,J02_VTA!G14,J03_VTA!G14,J04_VTA!G14,J05_VTA!G14,J06_VTA!G14,J07_VTA!G14,J08_VTA!G14,J09_VTA!G14,J10_VTA!G14,J11_VTA!G14,J12_VTA!G14,J13_VTA!G14) -> 63 | H10: =SUM(J01_IDA!H14,J02_IDA!H14,J03_IDA!H14,J04_IDA!H14,J05_IDA!H14,J06_IDA!H14,J07_IDA!H14,J08_IDA!H14,J09_IDA!H14,J10_IDA!H14,J11_IDA!H14,J12_IDA!H14,J13_IDA!H14,J01_VTA!H14,J02_VTA!H14,J03_VTA!H14,J04_VTA!H14,J05_VTA!H14,J06_VTA!H14,J07_VTA!H14,J08_VTA!H14,J09_VTA!H14,J10_VTA!H14,J11_VTA!H14,J12_VTA!H14,J13_VTA!H14) -> 0 | I10: =SUM(J01_IDA!J14,J02_IDA!J14,J03_IDA!J14,J04_IDA!J14,J05_IDA!J14,J06_IDA!J14,J07_IDA!J14,J08_IDA!J14,J09_IDA!J14,J10_IDA!J14,J11_IDA!J14,J12_IDA!J14,J13_IDA!J14,J01_VTA!J14,J02_VTA!J14,J03_VTA!J14,J04_VTA!J14,J05_VTA!J14,J06_VTA!J14,J07_VTA!J14,J08_VTA!J14,J09_VTA!J14,J10_VTA!J14,J11_VTA!J14,J12_VTA!J14,J13_VTA!J14) -> 0 | J10: =SUM(J01_IDA!K14,J02_IDA!K14,J03_IDA!K14,J04_IDA!K14,J05_IDA!K14,J06_IDA!K14,J07_IDA!K14,J08_IDA!K14,J09_IDA!K14,J10_IDA!K14,J11_IDA!K14,J12_IDA!K14,J13_IDA!K14,J01_VTA!K14,J02_VTA!K14,J03_VTA!K14,J04_VTA!K14,J05_VTA!K14,J06_VTA!K14,J07_VTA!K14,J08_VTA!K14,J09_VTA!K14,J10_VTA!K14,J11_VTA!K14,J12_VTA!K14,J13_VTA!K14) -> 0 | K10: =SUM(J01_IDA!L14,J02_IDA!L14,J03_IDA!L14,J04_IDA!L14,J05_IDA!L14,J06_IDA!L14,J07_IDA!L14,J08_IDA!L14,J09_IDA!L14,J10_IDA!L14,J11_IDA!L14,J12_IDA!L14,J13_IDA!L14,J01_VTA!L14,J02_VTA!L14,J03_VTA!L14,J04_VTA!L14,J05_VTA!L14,J06_VTA!L14,J07_VTA!L14,J08_VTA!L14,J09_VTA!L14,J10_VTA!L14,J11_VTA!L14,J12_VTA!L14,J13_VTA!L14) -> 0 | L10: =SUM(--(J01_IDA!M14="SÍ"),--(J02_IDA!M14="SÍ"),--(J03_IDA!M14="SÍ"),--(J04_IDA!M14="SÍ"),--(J05_IDA!M14="SÍ"),--(J06_IDA!M14="SÍ"),--(J07_IDA!M14="SÍ"),--(J08_IDA!M14="SÍ"),--(J09_IDA!M14="SÍ"),--(J10_IDA!M14="SÍ"),--(J11_IDA!M14="SÍ"),--(J12_IDA!M14="SÍ"),--(J13_IDA!M14="SÍ"),--(J01_VTA!M14="SÍ"),--(J02_VTA!M14="SÍ"),--(J03_VTA!M14="SÍ"),--(J04_VTA!M14="SÍ"),--(J05_VTA!M14="SÍ"),--(J06_VTA!M14="SÍ"),--(J07_VTA!M14="SÍ"),--(J08_VTA!M14="SÍ"),--(J09_VTA!M14="SÍ"),--(J10_VTA!M14="SÍ"),--(J11_VTA!M14="SÍ"),--(J12_VTA!M14="SÍ"),--(J13_VTA!M14="SÍ")) -> 0 | M10: =SUM(J01_IDA!I14,J02_IDA!I14,J03_IDA!I14,J04_IDA!I14,J05_IDA!I14,J06_IDA!I14,J07_IDA!I14,J08_IDA!I14,J09_IDA!I14,J10_IDA!I14,J11_IDA!I14,J12_IDA!I14,J13_IDA!I14,J01_VTA!I14,J02_VTA!I14,J03_VTA!I14,J04_VTA!I14,J05_VTA!I14,J06_VTA!I14,J07_VTA!I14,J08_VTA!I14,J09_VTA!I14,J10_VTA!I14,J11_VTA!I14,J12_VTA!I14,J13_VTA!I14) -> 0
A11: 6 | B11: Patri | C11: M.C. | D11: =SUM(--(J01_IDA!D15<>"NO CONVOCADA")*--(J01_IDA!D15<>""),--(J02_IDA!D15<>"NO CONVOCADA")*--(J02_IDA!D15<>""),--(J03_IDA!D15<>"NO CONVOCADA")*--(J03_IDA!D15<>""),--(J04_IDA!D15<>"NO CONVOCADA")*--(J04_IDA!D15<>""),--(J05_IDA!D15<>"NO CONVOCADA")*--(J05_IDA!D15<>""),--(J06_IDA!D15<>"NO CONVOCADA")*--(J06_IDA!D15<>""),--(J07_IDA!D15<>"NO CONVOCADA")*--(J07_IDA!D15<>""),--(J08_IDA!D15<>"NO CONVOCADA")*--(J08_IDA!D15<>""),--(J09_IDA!D15<>"NO CONVOCADA")*--(J09_IDA!D15<>""),--(J10_IDA!D15<>"NO CONVOCADA")*--(J10_IDA!D15<>""),--(J11_IDA!D15<>"NO CONVOCADA")*--(J11_IDA!D15<>""),--(J12_IDA!D15<>"NO CONVOCADA")*--(J12_IDA!D15<>""),--(J13_IDA!D15<>"NO CONVOCADA")*--(J13_IDA!D15<>""),--(J01_VTA!D15<>"NO CONVOCADA")*--(J01_VTA!D15<>""),--(J02_VTA!D15<>"NO CONVOCADA")*--(J02_VTA!D15<>""),--(J03_VTA!D15<>"NO CONVOCADA")*--(J03_VTA!D15<>""),--(J04_VTA!D15<>"NO CONVOCADA")*--(J04_VTA!D15<>""),--(J05_VTA!D15<>"NO CONVOCADA")*--(J05_VTA!D15<>""),--(J06_VTA!D15<>"NO CONVOCADA")*--(J06_VTA!D15<>""),--(J07_VTA!D15<>"NO CONVOCADA")*--(J07_VTA!D15<>""),--(J08_VTA!D15<>"NO CONVOCADA")*--(J08_VTA!D15<>""),--(J09_VTA!D15<>"NO CONVOCADA")*--(J09_VTA!D15<>""),--(J10_VTA!D15<>"NO CONVOCADA")*--(J10_VTA!D15<>""),--(J11_VTA!D15<>"NO CONVOCADA")*--(J11_VTA!D15<>""),--(J12_VTA!D15<>"NO CONVOCADA")*--(J12_VTA!D15<>""),--(J13_VTA!D15<>"NO CONVOCADA")*--(J13_VTA!D15<>"")) -> 1 | E11: =SUM(--(J01_IDA!D15="TITULAR"),--(J02_IDA!D15="TITULAR"),--(J03_IDA!D15="TITULAR"),--(J04_IDA!D15="TITULAR"),--(J05_IDA!D15="TITULAR"),--(J06_IDA!D15="TITULAR"),--(J07_IDA!D15="TITULAR"),--(J08_IDA!D15="TITULAR"),--(J09_IDA!D15="TITULAR"),--(J10_IDA!D15="TITULAR"),--(J11_IDA!D15="TITULAR"),--(J12_IDA!D15="TITULAR"),--(J13_IDA!D15="TITULAR"),--(J01_VTA!D15="TITULAR"),--(J02_VTA!D15="TITULAR"),--(J03_VTA!D15="TITULAR"),--(J04_VTA!D15="TITULAR"),--(J05_VTA!D15="TITULAR"),--(J06_VTA!D15="TITULAR"),--(J07_VTA!D15="TITULAR"),--(J08_VTA!D15="TITULAR"),--(J09_VTA!D15="TITULAR"),--(J10_VTA!D15="TITULAR"),--(J11_VTA!D15="TITULAR"),--(J12_VTA!D15="TITULAR"),--(J13_VTA!D15="TITULAR")) -> 1 | F11: =SUM(--(J01_IDA!D15="SUPLENTE"),--(J02_IDA!D15="SUPLENTE"),--(J03_IDA!D15="SUPLENTE"),--(J04_IDA!D15="SUPLENTE"),--(J05_IDA!D15="SUPLENTE"),--(J06_IDA!D15="SUPLENTE"),--(J07_IDA!D15="SUPLENTE"),--(J08_IDA!D15="SUPLENTE"),--(J09_IDA!D15="SUPLENTE"),--(J10_IDA!D15="SUPLENTE"),--(J11_IDA!D15="SUPLENTE"),--(J12_IDA!D15="SUPLENTE"),--(J13_IDA!D15="SUPLENTE"),--(J01_VTA!D15="SUPLENTE"),--(J02_VTA!D15="SUPLENTE"),--(J03_VTA!D15="SUPLENTE"),--(J04_VTA!D15="SUPLENTE"),--(J05_VTA!D15="SUPLENTE"),--(J06_VTA!D15="SUPLENTE"),--(J07_VTA!D15="SUPLENTE"),--(J08_VTA!D15="SUPLENTE"),--(J09_VTA!D15="SUPLENTE"),--(J10_VTA!D15="SUPLENTE"),--(J11_VTA!D15="SUPLENTE"),--(J12_VTA!D15="SUPLENTE"),--(J13_VTA!D15="SUPLENTE")) -> 0 | G11: =SUM(J01_IDA!G15,J02_IDA!G15,J03_IDA!G15,J04_IDA!G15,J05_IDA!G15,J06_IDA!G15,J07_IDA!G15,J08_IDA!G15,J09_IDA!G15,J10_IDA!G15,J11_IDA!G15,J12_IDA!G15,J13_IDA!G15,J01_VTA!G15,J02_VTA!G15,J03_VTA!G15,J04_VTA!G15,J05_VTA!G15,J06_VTA!G15,J07_VTA!G15,J08_VTA!G15,J09_VTA!G15,J10_VTA!G15,J11_VTA!G15,J12_VTA!G15,J13_VTA!G15) -> 64 | H11: =SUM(J01_IDA!H15,J02_IDA!H15,J03_IDA!H15,J04_IDA!H15,J05_IDA!H15,J06_IDA!H15,J07_IDA!H15,J08_IDA!H15,J09_IDA!H15,J10_IDA!H15,J11_IDA!H15,J12_IDA!H15,J13_IDA!H15,J01_VTA!H15,J02_VTA!H15,J03_VTA!H15,J04_VTA!H15,J05_VTA!H15,J06_VTA!H15,J07_VTA!H15,J08_VTA!H15,J09_VTA!H15,J10_VTA!H15,J11_VTA!H15,J12_VTA!H15,J13_VTA!H15) -> 0 | I11: =SUM(J01_IDA!J15,J02_IDA!J15,J03_IDA!J15,J04_IDA!J15,J05_IDA!J15,J06_IDA!J15,J07_IDA!J15,J08_IDA!J15,J09_IDA!J15,J10_IDA!J15,J11_IDA!J15,J12_IDA!J15,J13_IDA!J15,J01_VTA!J15,J02_VTA!J15,J03_VTA!J15,J04_VTA!J15,J05_VTA!J15,J06_VTA!J15,J07_VTA!J15,J08_VTA!J15,J09_VTA!J15,J10_VTA!J15,J11_VTA!J15,J12_VTA!J15,J13_VTA!J15) -> 0 | J11: =SUM(J01_IDA!K15,J02_IDA!K15,J03_IDA!K15,J04_IDA!K15,J05_IDA!K15,J06_IDA!K15,J07_IDA!K15,J08_IDA!K15,J09_IDA!K15,J10_IDA!K15,J11_IDA!K15,J12_IDA!K15,J13_IDA!K15,J01_VTA!K15,J02_VTA!K15,J03_VTA!K15,J04_VTA!K15,J05_VTA!K15,J06_VTA!K15,J07_VTA!K15,J08_VTA!K15,J09_VTA!K15,J10_VTA!K15,J11_VTA!K15,J12_VTA!K15,J13_VTA!K15) -> 0 | K11: =SUM(J01_IDA!L15,J02_IDA!L15,J03_IDA!L15,J04_IDA!L15,J05_IDA!L15,J06_IDA!L15,J07_IDA!L15,J08_IDA!L15,J09_IDA!L15,J10_IDA!L15,J11_IDA!L15,J12_IDA!L15,J13_IDA!L15,J01_VTA!L15,J02_VTA!L15,J03_VTA!L15,J04_VTA!L15,J05_VTA!L15,J06_VTA!L15,J07_VTA!L15,J08_VTA!L15,J09_VTA!L15,J10_VTA!L15,J11_VTA!L15,J12_VTA!L15,J13_VTA!L15) -> 0 | L11: =SUM(--(J01_IDA!M15="SÍ"),--(J02_IDA!M15="SÍ"),--(J03_IDA!M15="SÍ"),--(J04_IDA!M15="SÍ"),--(J05_IDA!M15="SÍ"),--(J06_IDA!M15="SÍ"),--(J07_IDA!M15="SÍ"),--(J08_IDA!M15="SÍ"),--(J09_IDA!M15="SÍ"),--(J10_IDA!M15="SÍ"),--(J11_IDA!M15="SÍ"),--(J12_IDA!M15="SÍ"),--(J13_IDA!M15="SÍ"),--(J01_VTA!M15="SÍ"),--(J02_VTA!M15="SÍ"),--(J03_VTA!M15="SÍ"),--(J04_VTA!M15="SÍ"),--(J05_VTA!M15="SÍ"),--(J06_VTA!M15="SÍ"),--(J07_VTA!M15="SÍ"),--(J08_VTA!M15="SÍ"),--(J09_VTA!M15="SÍ"),--(J10_VTA!M15="SÍ"),--(J11_VTA!M15="SÍ"),--(J12_VTA!M15="SÍ"),--(J13_VTA!M15="SÍ")) -> 0 | M11: =SUM(J01_IDA!I15,J02_IDA!I15,J03_IDA!I15,J04_IDA!I15,J05_IDA!I15,J06_IDA!I15,J07_IDA!I15,J08_IDA!I15,J09_IDA!I15,J10_IDA!I15,J11_IDA!I15,J12_IDA!I15,J13_IDA!I15,J01_VTA!I15,J02_VTA!I15,J03_VTA!I15,J04_VTA!I15,J05_VTA!I15,J06_VTA!I15,J07_VTA!I15,J08_VTA!I15,J09_VTA!I15,J10_VTA!I15,J11_VTA!I15,J12_VTA!I15,J13_VTA!I15) -> 0
A12: 7 | B12: Nerea | C12: EXT. | D12: =SUM(--(J01_IDA!D16<>"NO CONVOCADA")*--(J01_IDA!D16<>""),--(J02_IDA!D16<>"NO CONVOCADA")*--(J02_IDA!D16<>""),--(J03_IDA!D16<>"NO CONVOCADA")*--(J03_IDA!D16<>""),--(J04_IDA!D16<>"NO CONVOCADA")*--(J04_IDA!D16<>""),--(J05_IDA!D16<>"NO CONVOCADA")*--(J05_IDA!D16<>""),--(J06_IDA!D16<>"NO CONVOCADA")*--(J06_IDA!D16<>""),--(J07_IDA!D16<>"NO CONVOCADA")*--(J07_IDA!D16<>""),--(J08_IDA!D16<>"NO CONVOCADA")*--(J08_IDA!D16<>""),--(J09_IDA!D16<>"NO CONVOCADA")*--(J09_IDA!D16<>""),--(J10_IDA!D16<>"NO CONVOCADA")*--(J10_IDA!D16<>""),--(J11_IDA!D16<>"NO CONVOCADA")*--(J11_IDA!D16<>""),--(J12_IDA!D16<>"NO CONVOCADA")*--(J12_IDA!D16<>""),--(J13_IDA!D16<>"NO CONVOCADA")*--(J13_IDA!D16<>""),--(J01_VTA!D16<>"NO CONVOCADA")*--(J01_VTA!D16<>""),--(J02_VTA!D16<>"NO CONVOCADA")*--(J02_VTA!D16<>""),--(J03_VTA!D16<>"NO CONVOCADA")*--(J03_VTA!D16<>""),--(J04_VTA!D16<>"NO CONVOCADA")*--(J04_VTA!D16<>""),--(J05_VTA!D16<>"NO CONVOCADA")*--(J05_VTA!D16<>""),--(J06_VTA!D16<>"NO CONVOCADA")*--(J06_VTA!D16<>""),--(J07_VTA!D16<>"NO CONVOCADA")*--(J07_VTA!D16<>""),--(J08_VTA!D16<>"NO CONVOCADA")*--(J08_VTA!D16<>""),--(J09_VTA!D16<>"NO CONVOCADA")*--(J09_VTA!D16<>""),--(J10_VTA!D16<>"NO CONVOCADA")*--(J10_VTA!D16<>""),--(J11_VTA!D16<>"NO CONVOCADA")*--(J11_VTA!D16<>""),--(J12_VTA!D16<>"NO CONVOCADA")*--(J12_VTA!D16<>""),--(J13_VTA!D16<>"NO CONVOCADA")*--(J13_VTA!D16<>"")) -> 1 | E12: =SUM(--(J01_IDA!D16="TITULAR"),--(J02_IDA!D16="TITULAR"),--(J03_IDA!D16="TITULAR"),--(J04_IDA!D16="TITULAR"),--(J05_IDA!D16="TITULAR"),--(J06_IDA!D16="TITULAR"),--(J07_IDA!D16="TITULAR"),--(J08_IDA!D16="TITULAR"),--(J09_IDA!D16="TITULAR"),--(J10_IDA!D16="TITULAR"),--(J11_IDA!D16="TITULAR"),--(J12_IDA!D16="TITULAR"),--(J13_IDA!D16="TITULAR"),--(J01_VTA!D16="TITULAR"),--(J02_VTA!D16="TITULAR"),--(J03_VTA!D16="TITULAR"),--(J04_VTA!D16="TITULAR"),--(J05_VTA!D16="TITULAR"),--(J06_VTA!D16="TITULAR"),--(J07_VTA!D16="TITULAR"),--(J08_VTA!D16="TITULAR"),--(J09_VTA!D16="TITULAR"),--(J10_VTA!D16="TITULAR"),--(J11_VTA!D16="TITULAR"),--(J12_VTA!D16="TITULAR"),--(J13_VTA!D16="TITULAR")) -> 1 | F12: =SUM(--(J01_IDA!D16="SUPLENTE"),--(J02_IDA!D16="SUPLENTE"),--(J03_IDA!D16="SUPLENTE"),--(J04_IDA!D16="SUPLENTE"),--(J05_IDA!D16="SUPLENTE"),--(J06_IDA!D16="SUPLENTE"),--(J07_IDA!D16="SUPLENTE"),--(J08_IDA!D16="SUPLENTE"),--(J09_IDA!D16="SUPLENTE"),--(J10_IDA!D16="SUPLENTE"),--(J11_IDA!D16="SUPLENTE"),--(J12_IDA!D16="SUPLENTE"),--(J13_IDA!D16="SUPLENTE"),--(J01_VTA!D16="SUPLENTE"),--(J02_VTA!D16="SUPLENTE"),--(J03_VTA!D16="SUPLENTE"),--(J04_VTA!D16="SUPLENTE"),--(J05_VTA!D16="SUPLENTE"),--(J06_VTA!D16="SUPLENTE"),--(J07_VTA!D16="SUPLENTE"),--(J08_VTA!D16="SUPLENTE"),--(J09_VTA!D16="SUPLENTE"),--(J10_VTA!D16="SUPLENTE"),--(J11_VTA!D16="SUPLENTE"),--(J12_VTA!D16="SUPLENTE"),--(J13_VTA!D16="SUPLENTE")) -> 0 | G12: =SUM(J01_IDA!G16,J02_IDA!G16,J03_IDA!G16,J04_IDA!G16,J05_IDA!G16,J06_IDA!G16,J07_IDA!G16,J08_IDA!G16,J09_IDA!G16,J10_IDA!G16,J11_IDA!G16,J12_IDA!G16,J13_IDA!G16,J01_VTA!G16,J02_VTA!G16,J03_VTA!G16,J04_VTA!G16,J05_VTA!G16,J06_VTA!G16,J07_VTA!G16,J08_VTA!G16,J09_VTA!G16,J10_VTA!G16,J11_VTA!G16,J12_VTA!G16,J13_VTA!G16) -> 56 | H12: =SUM(J01_IDA!H16,J02_IDA!H16,J03_IDA!H16,J04_IDA!H16,J05_IDA!H16,J06_IDA!H16,J07_IDA!H16,J08_IDA!H16,J09_IDA!H16,J10_IDA!H16,J11_IDA!H16,J12_IDA!H16,J13_IDA!H16,J01_VTA!H16,J02_VTA!H16,J03_VTA!H16,J04_VTA!H16,J05_VTA!H16,J06_VTA!H16,J07_VTA!H16,J08_VTA!H16,J09_VTA!H16,J10_VTA!H16,J11_VTA!H16,J12_VTA!H16,J13_VTA!H16) -> 0 | I12: =SUM(J01_IDA!J16,J02_IDA!J16,J03_IDA!J16,J04_IDA!J16,J05_IDA!J16,J06_IDA!J16,J07_IDA!J16,J08_IDA!J16,J09_IDA!J16,J10_IDA!J16,J11_IDA!J16,J12_IDA!J16,J13_IDA!J16,J01_VTA!J16,J02_VTA!J16,J03_VTA!J16,J04_VTA!J16,J05_VTA!J16,J06_VTA!J16,J07_VTA!J16,J08_VTA!J16,J09_VTA!J16,J10_VTA!J16,J11_VTA!J16,J12_VTA!J16,J13_VTA!J16) -> 0 | J12: =SUM(J01_IDA!K16,J02_IDA!K16,J03_IDA!K16,J04_IDA!K16,J05_IDA!K16,J06_IDA!K16,J07_IDA!K16,J08_IDA!K16,J09_IDA!K16,J10_IDA!K16,J11_IDA!K16,J12_IDA!K16,J13_IDA!K16,J01_VTA!K16,J02_VTA!K16,J03_VTA!K16,J04_VTA!K16,J05_VTA!K16,J06_VTA!K16,J07_VTA!K16,J08_VTA!K16,J09_VTA!K16,J10_VTA!K16,J11_VTA!K16,J12_VTA!K16,J13_VTA!K16) -> 0 | K12: =SUM(J01_IDA!L16,J02_IDA!L16,J03_IDA!L16,J04_IDA!L16,J05_IDA!L16,J06_IDA!L16,J07_IDA!L16,J08_IDA!L16,J09_IDA!L16,J10_IDA!L16,J11_IDA!L16,J12_IDA!L16,J13_IDA!L16,J01_VTA!L16,J02_VTA!L16,J03_VTA!L16,J04_VTA!L16,J05_VTA!L16,J06_VTA!L16,J07_VTA!L16,J08_VTA!L16,J09_VTA!L16,J10_VTA!L16,J11_VTA!L16,J12_VTA!L16,J13_VTA!L16) -> 0 | L12: =SUM(--(J01_IDA!M16="SÍ"),--(J02_IDA!M16="SÍ"),--(J03_IDA!M16="SÍ"),--(J04_IDA!M16="SÍ"),--(J05_IDA!M16="SÍ"),--(J06_IDA!M16="SÍ"),--(J07_IDA!M16="SÍ"),--(J08_IDA!M16="SÍ"),--(J09_IDA!M16="SÍ"),--(J10_IDA!M16="SÍ"),--(J11_IDA!M16="SÍ"),--(J12_IDA!M16="SÍ"),--(J13_IDA!M16="SÍ"),--(J01_VTA!M16="SÍ"),--(J02_VTA!M16="SÍ"),--(J03_VTA!M16="SÍ"),--(J04_VTA!M16="SÍ"),--(J05_VTA!M16="SÍ"),--(J06_VTA!M16="SÍ"),--(J07_VTA!M16="SÍ"),--(J08_VTA!M16="SÍ"),--(J09_VTA!M16="SÍ"),--(J10_VTA!M16="SÍ"),--(J11_VTA!M16="SÍ"),--(J12_VTA!M16="SÍ"),--(J13_VTA!M16="SÍ")) -> 0 | M12: =SUM(J01_IDA!I16,J02_IDA!I16,J03_IDA!I16,J04_IDA!I16,J05_IDA!I16,J06_IDA!I16,J07_IDA!I16,J08_IDA!I16,J09_IDA!I16,J10_IDA!I16,J11_IDA!I16,J12_IDA!I16,J13_IDA!I16,J01_VTA!I16,J02_VTA!I16,J03_VTA!I16,J04_VTA!I16,J05_VTA!I16,J06_VTA!I16,J07_VTA!I16,J08_VTA!I16,J09_VTA!I16,J10_VTA!I16,J11_VTA!I16,J12_VTA!I16,J13_VTA!I16) -> 0
A13: 8 | B13: Caye | C13: L.I. / M.C. | D13: =SUM(--(J01_IDA!D17<>"NO CONVOCADA")*--(J01_IDA!D17<>""),--(J02_IDA!D17<>"NO CONVOCADA")*--(J02_IDA!D17<>""),--(J03_IDA!D17<>"NO CONVOCADA")*--(J03_IDA!D17<>""),--(J04_IDA!D17<>"NO CONVOCADA")*--(J04_IDA!D17<>""),--(J05_IDA!D17<>"NO CONVOCADA")*--(J05_IDA!D17<>""),--(J06_IDA!D17<>"NO CONVOCADA")*--(J06_IDA!D17<>""),--(J07_IDA!D17<>"NO CONVOCADA")*--(J07_IDA!D17<>""),--(J08_IDA!D17<>"NO CONVOCADA")*--(J08_IDA!D17<>""),--(J09_IDA!D17<>"NO CONVOCADA")*--(J09_IDA!D17<>""),--(J10_IDA!D17<>"NO CONVOCADA")*--(J10_IDA!D17<>""),--(J11_IDA!D17<>"NO CONVOCADA")*--(J11_IDA!D17<>""),--(J12_IDA!D17<>"NO CONVOCADA")*--(J12_IDA!D17<>""),--(J13_IDA!D17<>"NO CONVOCADA")*--(J13_IDA!D17<>""),--(J01_VTA!D17<>"NO CONVOCADA")*--(J01_VTA!D17<>""),--(J02_VTA!D17<>"NO CONVOCADA")*--(J02_VTA!D17<>""),--(J03_VTA!D17<>"NO CONVOCADA")*--(J03_VTA!D17<>""),--(J04_VTA!D17<>"NO CONVOCADA")*--(J04_VTA!D17<>""),--(J05_VTA!D17<>"NO CONVOCADA")*--(J05_VTA!D17<>""),--(J06_VTA!D17<>"NO CONVOCADA")*--(J06_VTA!D17<>""),--(J07_VTA!D17<>"NO CONVOCADA")*--(J07_VTA!D17<>""),--(J08_VTA!D17<>"NO CONVOCADA")*--(J08_VTA!D17<>""),--(J09_VTA!D17<>"NO CONVOCADA")*--(J09_VTA!D17<>""),--(J10_VTA!D17<>"NO CONVOCADA")*--(J10_VTA!D17<>""),--(J11_VTA!D17<>"NO CONVOCADA")*--(J11_VTA!D17<>""),--(J12_VTA!D17<>"NO CONVOCADA")*--(J12_VTA!D17<>""),--(J13_VTA!D17<>"NO CONVOCADA")*--(J13_VTA!D17<>"")) -> 1 | E13: =SUM(--(J01_IDA!D17="TITULAR"),--(J02_IDA!D17="TITULAR"),--(J03_IDA!D17="TITULAR"),--(J04_IDA!D17="TITULAR"),--(J05_IDA!D17="TITULAR"),--(J06_IDA!D17="TITULAR"),--(J07_IDA!D17="TITULAR"),--(J08_IDA!D17="TITULAR"),--(J09_IDA!D17="TITULAR"),--(J10_IDA!D17="TITULAR"),--(J11_IDA!D17="TITULAR"),--(J12_IDA!D17="TITULAR"),--(J13_IDA!D17="TITULAR"),--(J01_VTA!D17="TITULAR"),--(J02_VTA!D17="TITULAR"),--(J03_VTA!D17="TITULAR"),--(J04_VTA!D17="TITULAR"),--(J05_VTA!D17="TITULAR"),--(J06_VTA!D17="TITULAR"),--(J07_VTA!D17="TITULAR"),--(J08_VTA!D17="TITULAR"),--(J09_VTA!D17="TITULAR"),--(J10_VTA!D17="TITULAR"),--(J11_VTA!D17="TITULAR"),--(J12_VTA!D17="TITULAR"),--(J13_VTA!D17="TITULAR")) -> 1 | F13: =SUM(--(J01_IDA!D17="SUPLENTE"),--(J02_IDA!D17="SUPLENTE"),--(J03_IDA!D17="SUPLENTE"),--(J04_IDA!D17="SUPLENTE"),--(J05_IDA!D17="SUPLENTE"),--(J06_IDA!D17="SUPLENTE"),--(J07_IDA!D17="SUPLENTE"),--(J08_IDA!D17="SUPLENTE"),--(J09_IDA!D17="SUPLENTE"),--(J10_IDA!D17="SUPLENTE"),--(J11_IDA!D17="SUPLENTE"),--(J12_IDA!D17="SUPLENTE"),--(J13_IDA!D17="SUPLENTE"),--(J01_VTA!D17="SUPLENTE"),--(J02_VTA!D17="SUPLENTE"),--(J03_VTA!D17="SUPLENTE"),--(J04_VTA!D17="SUPLENTE"),--(J05_VTA!D17="SUPLENTE"),--(J06_VTA!D17="SUPLENTE"),--(J07_VTA!D17="SUPLENTE"),--(J08_VTA!D17="SUPLENTE"),--(J09_VTA!D17="SUPLENTE"),--(J10_VTA!D17="SUPLENTE"),--(J11_VTA!D17="SUPLENTE"),--(J12_VTA!D17="SUPLENTE"),--(J13_VTA!D17="SUPLENTE")) -> 0 | G13: =SUM(J01_IDA!G17,J02_IDA!G17,J03_IDA!G17,J04_IDA!G17,J05_IDA!G17,J06_IDA!G17,J07_IDA!G17,J08_IDA!G17,J09_IDA!G17,J10_IDA!G17,J11_IDA!G17,J12_IDA!G17,J13_IDA!G17,J01_VTA!G17,J02_VTA!G17,J03_VTA!G17,J04_VTA!G17,J05_VTA!G17,J06_VTA!G17,J07_VTA!G17,J08_VTA!G17,J09_VTA!G17,J10_VTA!G17,J11_VTA!G17,J12_VTA!G17,J13_VTA!G17) -> 43 | H13: =SUM(J01_IDA!H17,J02_IDA!H17,J03_IDA!H17,J04_IDA!H17,J05_IDA!H17,J06_IDA!H17,J07_IDA!H17,J08_IDA!H17,J09_IDA!H17,J10_IDA!H17,J11_IDA!H17,J12_IDA!H17,J13_IDA!H17,J01_VTA!H17,J02_VTA!H17,J03_VTA!H17,J04_VTA!H17,J05_VTA!H17,J06_VTA!H17,J07_VTA!H17,J08_VTA!H17,J09_VTA!H17,J10_VTA!H17,J11_VTA!H17,J12_VTA!H17,J13_VTA!H17) -> 1 | I13: =SUM(J01_IDA!J17,J02_IDA!J17,J03_IDA!J17,J04_IDA!J17,J05_IDA!J17,J06_IDA!J17,J07_IDA!J17,J08_IDA!J17,J09_IDA!J17,J10_IDA!J17,J11_IDA!J17,J12_IDA!J17,J13_IDA!J17,J01_VTA!J17,J02_VTA!J17,J03_VTA!J17,J04_VTA!J17,J05_VTA!J17,J06_VTA!J17,J07_VTA!J17,J08_VTA!J17,J09_VTA!J17,J10_VTA!J17,J11_VTA!J17,J12_VTA!J17,J13_VTA!J17) -> 0 | J13: =SUM(J01_IDA!K17,J02_IDA!K17,J03_IDA!K17,J04_IDA!K17,J05_IDA!K17,J06_IDA!K17,J07_IDA!K17,J08_IDA!K17,J09_IDA!K17,J10_IDA!K17,J11_IDA!K17,J12_IDA!K17,J13_IDA!K17,J01_VTA!K17,J02_VTA!K17,J03_VTA!K17,J04_VTA!K17,J05_VTA!K17,J06_VTA!K17,J07_VTA!K17,J08_VTA!K17,J09_VTA!K17,J10_VTA!K17,J11_VTA!K17,J12_VTA!K17,J13_VTA!K17) -> 0 | K13: =SUM(J01_IDA!L17,J02_IDA!L17,J03_IDA!L17,J04_IDA!L17,J05_IDA!L17,J06_IDA!L17,J07_IDA!L17,J08_IDA!L17,J09_IDA!L17,J10_IDA!L17,J11_IDA!L17,J12_IDA!L17,J13_IDA!L17,J01_VTA!L17,J02_VTA!L17,J03_VTA!L17,J04_VTA!L17,J05_VTA!L17,J06_VTA!L17,J07_VTA!L17,J08_VTA!L17,J09_VTA!L17,J10_VTA!L17,J11_VTA!L17,J12_VTA!L17,J13_VTA!L17) -> 0 | L13: =SUM(--(J01_IDA!M17="SÍ"),--(J02_IDA!M17="SÍ"),--(J03_IDA!M17="SÍ"),--(J04_IDA!M17="SÍ"),--(J05_IDA!M17="SÍ"),--(J06_IDA!M17="SÍ"),--(J07_IDA!M17="SÍ"),--(J08_IDA!M17="SÍ"),--(J09_IDA!M17="SÍ"),--(J10_IDA!M17="SÍ"),--(J11_IDA!M17="SÍ"),--(J12_IDA!M17="SÍ"),--(J13_IDA!M17="SÍ"),--(J01_VTA!M17="SÍ"),--(J02_VTA!M17="SÍ"),--(J03_VTA!M17="SÍ"),--(J04_VTA!M17="SÍ"),--(J05_VTA!M17="SÍ"),--(J06_VTA!M17="SÍ"),--(J07_VTA!M17="SÍ"),--(J08_VTA!M17="SÍ"),--(J09_VTA!M17="SÍ"),--(J10_VTA!M17="SÍ"),--(J11_VTA!M17="SÍ"),--(J12_VTA!M17="SÍ"),--(J13_VTA!M17="SÍ")) -> 0 | M13: =SUM(J01_IDA!I17,J02_IDA!I17,J03_IDA!I17,J04_IDA!I17,J05_IDA!I17,J06_IDA!I17,J07_IDA!I17,J08_IDA!I17,J09_IDA!I17,J10_IDA!I17,J11_IDA!I17,J12_IDA!I17,J13_IDA!I17,J01_VTA!I17,J02_VTA!I17,J03_VTA!I17,J04_VTA!I17,J05_VTA!I17,J06_VTA!I17,J07_VTA!I17,J08_VTA!I17,J09_VTA!I17,J10_VTA!I17,J11_VTA!I17,J12_VTA!I17,J13_VTA!I17) -> 0
A14: 9 | B14: Virginia | C14: DELANTERA / EXT. | D14: =SUM(--(J01_IDA!D18<>"NO CONVOCADA")*--(J01_IDA!D18<>""),--(J02_IDA!D18<>"NO CONVOCADA")*--(J02_IDA!D18<>""),--(J03_IDA!D18<>"NO CONVOCADA")*--(J03_IDA!D18<>""),--(J04_IDA!D18<>"NO CONVOCADA")*--(J04_IDA!D18<>""),--(J05_IDA!D18<>"NO CONVOCADA")*--(J05_IDA!D18<>""),--(J06_IDA!D18<>"NO CONVOCADA")*--(J06_IDA!D18<>""),--(J07_IDA!D18<>"NO CONVOCADA")*--(J07_IDA!D18<>""),--(J08_IDA!D18<>"NO CONVOCADA")*--(J08_IDA!D18<>""),--(J09_IDA!D18<>"NO CONVOCADA")*--(J09_IDA!D18<>""),--(J10_IDA!D18<>"NO CONVOCADA")*--(J10_IDA!D18<>""),--(J11_IDA!D18<>"NO CONVOCADA")*--(J11_IDA!D18<>""),--(J12_IDA!D18<>"NO CONVOCADA")*--(J12_IDA!D18<>""),--(J13_IDA!D18<>"NO CONVOCADA")*--(J13_IDA!D18<>""),--(J01_VTA!D18<>"NO CONVOCADA")*--(J01_VTA!D18<>""),--(J02_VTA!D18<>"NO CONVOCADA")*--(J02_VTA!D18<>""),--(J03_VTA!D18<>"NO CONVOCADA")*--(J03_VTA!D18<>""),--(J04_VTA!D18<>"NO CONVOCADA")*--(J04_VTA!D18<>""),--(J05_VTA!D18<>"NO CONVOCADA")*--(J05_VTA!D18<>""),--(J06_VTA!D18<>"NO CONVOCADA")*--(J06_VTA!D18<>""),--(J07_VTA!D18<>"NO CONVOCADA")*--(J07_VTA!D18<>""),--(J08_VTA!D18<>"NO CONVOCADA")*--(J08_VTA!D18<>""),--(J09_VTA!D18<>"NO CONVOCADA")*--(J09_VTA!D18<>""),--(J10_VTA!D18<>"NO CONVOCADA")*--(J10_VTA!D18<>""),--(J11_VTA!D18<>"NO CONVOCADA")*--(J11_VTA!D18<>""),--(J12_VTA!D18<>"NO CONVOCADA")*--(J12_VTA!D18<>""),--(J13_VTA!D18<>"NO CONVOCADA")*--(J13_VTA!D18<>"")) -> 1 | E14: =SUM(--(J01_IDA!D18="TITULAR"),--(J02_IDA!D18="TITULAR"),--(J03_IDA!D18="TITULAR"),--(J04_IDA!D18="TITULAR"),--(J05_IDA!D18="TITULAR"),--(J06_IDA!D18="TITULAR"),--(J07_IDA!D18="TITULAR"),--(J08_IDA!D18="TITULAR"),--(J09_IDA!D18="TITULAR"),--(J10_IDA!D18="TITULAR"),--(J11_IDA!D18="TITULAR"),--(J12_IDA!D18="TITULAR"),--(J13_IDA!D18="TITULAR"),--(J01_VTA!D18="TITULAR"),--(J02_VTA!D18="TITULAR"),--(J03_VTA!D18="TITULAR"),--(J04_VTA!D18="TITULAR"),--(J05_VTA!D18="TITULAR"),--(J06_VTA!D18="TITULAR"),--(J07_VTA!D18="TITULAR"),--(J08_VTA!D18="TITULAR"),--(J09_VTA!D18="TITULAR"),--(J10_VTA!D18="TITULAR"),--(J11_VTA!D18="TITULAR"),--(J12_VTA!D18="TITULAR"),--(J13_VTA!D18="TITULAR")) -> 1 | F14: =SUM(--(J01_IDA!D18="SUPLENTE"),--(J02_IDA!D18="SUPLENTE"),--(J03_IDA!D18="SUPLENTE"),--(J04_IDA!D18="SUPLENTE"),--(J05_IDA!D18="SUPLENTE"),--(J06_IDA!D18="SUPLENTE"),--(J07_IDA!D18="SUPLENTE"),--(J08_IDA!D18="SUPLENTE"),--(J09_IDA!D18="SUPLENTE"),--(J10_IDA!D18="SUPLENTE"),--(J11_IDA!D18="SUPLENTE"),--(J12_IDA!D18="SUPLENTE"),--(J13_IDA!D18="SUPLENTE"),--(J01_VTA!D18="SUPLENTE"),--(J02_VTA!D18="SUPLENTE"),--(J03_VTA!D18="SUPLENTE"),--(J04_VTA!D18="SUPLENTE"),--(J05_VTA!D18="SUPLENTE"),--(J06_VTA!D18="SUPLENTE"),--(J07_VTA!D18="SUPLENTE"),--(J08_VTA!D18="SUPLENTE"),--(J09_VTA!D18="SUPLENTE"),--(J10_VTA!D18="SUPLENTE"),--(J11_VTA!D18="SUPLENTE"),--(J12_VTA!D18="SUPLENTE"),--(J13_VTA!D18="SUPLENTE")) -> 0 | G14: =SUM(J01_IDA!G18,J02_IDA!G18,J03_IDA!G18,J04_IDA!G18,J05_IDA!G18,J06_IDA!G18,J07_IDA!G18,J08_IDA!G18,J09_IDA!G18,J10_IDA!G18,J11_IDA!G18,J12_IDA!G18,J13_IDA!G18,J01_VTA!G18,J02_VTA!G18,J03_VTA!G18,J04_VTA!G18,J05_VTA!G18,J06_VTA!G18,J07_VTA!G18,J08_VTA!G18,J09_VTA!G18,J10_VTA!G18,J11_VTA!G18,J12_VTA!G18,J13_VTA!G18) -> 64 | H14: =SUM(J01_IDA!H18,J02_IDA!H18,J03_IDA!H18,J04_IDA!H18,J05_IDA!H18,J06_IDA!H18,J07_IDA!H18,J08_IDA!H18,J09_IDA!H18,J10_IDA!H18,J11_IDA!H18,J12_IDA!H18,J13_IDA!H18,J01_VTA!H18,J02_VTA!H18,J03_VTA!H18,J04_VTA!H18,J05_VTA!H18,J06_VTA!H18,J07_VTA!H18,J08_VTA!H18,J09_VTA!H18,J10_VTA!H18,J11_VTA!H18,J12_VTA!H18,J13_VTA!H18) -> 0 | I14: =SUM(J01_IDA!J18,J02_IDA!J18,J03_IDA!J18,J04_IDA!J18,J05_IDA!J18,J06_IDA!J18,J07_IDA!J18,J08_IDA!J18,J09_IDA!J18,J10_IDA!J18,J11_IDA!J18,J12_IDA!J18,J13_IDA!J18,J01_VTA!J18,J02_VTA!J18,J03_VTA!J18,J04_VTA!J18,J05_VTA!J18,J06_VTA!J18,J07_VTA!J18,J08_VTA!J18,J09_VTA!J18,J10_VTA!J18,J11_VTA!J18,J12_VTA!J18,J13_VTA!J18) -> 0 | J14: =SUM(J01_IDA!K18,J02_IDA!K18,J03_IDA!K18,J04_IDA!K18,J05_IDA!K18,J06_IDA!K18,J07_IDA!K18,J08_IDA!K18,J09_IDA!K18,J10_IDA!K18,J11_IDA!K18,J12_IDA!K18,J13_IDA!K18,J01_VTA!K18,J02_VTA!K18,J03_VTA!K18,J04_VTA!K18,J05_VTA!K18,J06_VTA!K18,J07_VTA!K18,J08_VTA!K18,J09_VTA!K18,J10_VTA!K18,J11_VTA!K18,J12_VTA!K18,J13_VTA!K18) -> 0 | K14: =SUM(J01_IDA!L18,J02_IDA!L18,J03_IDA!L18,J04_IDA!L18,J05_IDA!L18,J06_IDA!L18,J07_IDA!L18,J08_IDA!L18,J09_IDA!L18,J10_IDA!L18,J11_IDA!L18,J12_IDA!L18,J13_IDA!L18,J01_VTA!L18,J02_VTA!L18,J03_VTA!L18,J04_VTA!L18,J05_VTA!L18,J06_VTA!L18,J07_VTA!L18,J08_VTA!L18,J09_VTA!L18,J10_VTA!L18,J11_VTA!L18,J12_VTA!L18,J13_VTA!L18) -> 0 | L14: =SUM(--(J01_IDA!M18="SÍ"),--(J02_IDA!M18="SÍ"),--(J03_IDA!M18="SÍ"),--(J04_IDA!M18="SÍ"),--(J05_IDA!M18="SÍ"),--(J06_IDA!M18="SÍ"),--(J07_IDA!M18="SÍ"),--(J08_IDA!M18="SÍ"),--(J09_IDA!M18="SÍ"),--(J10_IDA!M18="SÍ"),--(J11_IDA!M18="SÍ"),--(J12_IDA!M18="SÍ"),--(J13_IDA!M18="SÍ"),--(J01_VTA!M18="SÍ"),--(J02_VTA!M18="SÍ"),--(J03_VTA!M18="SÍ"),--(J04_VTA!M18="SÍ"),--(J05_VTA!M18="SÍ"),--(J06_VTA!M18="SÍ"),--(J07_VTA!M18="SÍ"),--(J08_VTA!M18="SÍ"),--(J09_VTA!M18="SÍ"),--(J10_VTA!M18="SÍ"),--(J11_VTA!M18="SÍ"),--(J12_VTA!M18="SÍ"),--(J13_VTA!M18="SÍ")) -> 0 | M14: =SUM(J01_IDA!I18,J02_IDA!I18,J03_IDA!I18,J04_IDA!I18,J05_IDA!I18,J06_IDA!I18,J07_IDA!I18,J08_IDA!I18,J09_IDA!I18,J10_IDA!I18,J11_IDA!I18,J12_IDA!I18,J13_IDA!I18,J01_VTA!I18,J02_VTA!I18,J03_VTA!I18,J04_VTA!I18,J05_VTA!I18,J06_VTA!I18,J07_VTA!I18,J08_VTA!I18,J09_VTA!I18,J10_VTA!I18,J11_VTA!I18,J12_VTA!I18,J13_VTA!I18) -> 0
A15: 10 | B15: Guzmán | C15: M.P. / EXT. | D15: =SUM(--(J01_IDA!D19<>"NO CONVOCADA")*--(J01_IDA!D19<>""),--(J02_IDA!D19<>"NO CONVOCADA")*--(J02_IDA!D19<>""),--(J03_IDA!D19<>"NO CONVOCADA")*--(J03_IDA!D19<>""),--(J04_IDA!D19<>"NO CONVOCADA")*--(J04_IDA!D19<>""),--(J05_IDA!D19<>"NO CONVOCADA")*--(J05_IDA!D19<>""),--(J06_IDA!D19<>"NO CONVOCADA")*--(J06_IDA!D19<>""),--(J07_IDA!D19<>"NO CONVOCADA")*--(J07_IDA!D19<>""),--(J08_IDA!D19<>"NO CONVOCADA")*--(J08_IDA!D19<>""),--(J09_IDA!D19<>"NO CONVOCADA")*--(J09_IDA!D19<>""),--(J10_IDA!D19<>"NO CONVOCADA")*--(J10_IDA!D19<>""),--(J11_IDA!D19<>"NO CONVOCADA")*--(J11_IDA!D19<>""),--(J12_IDA!D19<>"NO CONVOCADA")*--(J12_IDA!D19<>""),--(J13_IDA!D19<>"NO CONVOCADA")*--(J13_IDA!D19<>""),--(J01_VTA!D19<>"NO CONVOCADA")*--(J01_VTA!D19<>""),--(J02_VTA!D19<>"NO CONVOCADA")*--(J02_VTA!D19<>""),--(J03_VTA!D19<>"NO CONVOCADA")*--(J03_VTA!D19<>""),--(J04_VTA!D19<>"NO CONVOCADA")*--(J04_VTA!D19<>""),--(J05_VTA!D19<>"NO CONVOCADA")*--(J05_VTA!D19<>""),--(J06_VTA!D19<>"NO CONVOCADA")*--(J06_VTA!D19<>""),--(J07_VTA!D19<>"NO CONVOCADA")*--(J07_VTA!D19<>""),--(J08_VTA!D19<>"NO CONVOCADA")*--(J08_VTA!D19<>""),--(J09_VTA!D19<>"NO CONVOCADA")*--(J09_VTA!D19<>""),--(J10_VTA!D19<>"NO CONVOCADA")*--(J10_VTA!D19<>""),--(J11_VTA!D19<>"NO CONVOCADA")*--(J11_VTA!D19<>""),--(J12_VTA!D19<>"NO CONVOCADA")*--(J12_VTA!D19<>""),--(J13_VTA!D19<>"NO CONVOCADA")*--(J13_VTA!D19<>"")) -> 1 | E15: =SUM(--(J01_IDA!D19="TITULAR"),--(J02_IDA!D19="TITULAR"),--(J03_IDA!D19="TITULAR"),--(J04_IDA!D19="TITULAR"),--(J05_IDA!D19="TITULAR"),--(J06_IDA!D19="TITULAR"),--(J07_IDA!D19="TITULAR"),--(J08_IDA!D19="TITULAR"),--(J09_IDA!D19="TITULAR"),--(J10_IDA!D19="TITULAR"),--(J11_IDA!D19="TITULAR"),--(J12_IDA!D19="TITULAR"),--(J13_IDA!D19="TITULAR"),--(J01_VTA!D19="TITULAR"),--(J02_VTA!D19="TITULAR"),--(J03_VTA!D19="TITULAR"),--(J04_VTA!D19="TITULAR"),--(J05_VTA!D19="TITULAR"),--(J06_VTA!D19="TITULAR"),--(J07_VTA!D19="TITULAR"),--(J08_VTA!D19="TITULAR"),--(J09_VTA!D19="TITULAR"),--(J10_VTA!D19="TITULAR"),--(J11_VTA!D19="TITULAR"),--(J12_VTA!D19="TITULAR"),--(J13_VTA!D19="TITULAR")) -> 1 | F15: =SUM(--(J01_IDA!D19="SUPLENTE"),--(J02_IDA!D19="SUPLENTE"),--(J03_IDA!D19="SUPLENTE"),--(J04_IDA!D19="SUPLENTE"),--(J05_IDA!D19="SUPLENTE"),--(J06_IDA!D19="SUPLENTE"),--(J07_IDA!D19="SUPLENTE"),--(J08_IDA!D19="SUPLENTE"),--(J09_IDA!D19="SUPLENTE"),--(J10_IDA!D19="SUPLENTE"),--(J11_IDA!D19="SUPLENTE"),--(J12_IDA!D19="SUPLENTE"),--(J13_IDA!D19="SUPLENTE"),--(J01_VTA!D19="SUPLENTE"),--(J02_VTA!D19="SUPLENTE"),--(J03_VTA!D19="SUPLENTE"),--(J04_VTA!D19="SUPLENTE"),--(J05_VTA!D19="SUPLENTE"),--(J06_VTA!D19="SUPLENTE"),--(J07_VTA!D19="SUPLENTE"),--(J08_VTA!D19="SUPLENTE"),--(J09_VTA!D19="SUPLENTE"),--(J10_VTA!D19="SUPLENTE"),--(J11_VTA!D19="SUPLENTE"),--(J12_VTA!D19="SUPLENTE"),--(J13_VTA!D19="SUPLENTE")) -> 0 | G15: =SUM(J01_IDA!G19,J02_IDA!G19,J03_IDA!G19,J04_IDA!G19,J05_IDA!G19,J06_IDA!G19,J07_IDA!G19,J08_IDA!G19,J09_IDA!G19,J10_IDA!G19,J11_IDA!G19,J12_IDA!G19,J13_IDA!G19,J01_VTA!G19,J02_VTA!G19,J03_VTA!G19,J04_VTA!G19,J05_VTA!G19,J06_VTA!G19,J07_VTA!G19,J08_VTA!G19,J09_VTA!G19,J10_VTA!G19,J11_VTA!G19,J12_VTA!G19,J13_VTA!G19) -> 73 | H15: =SUM(J01_IDA!H19,J02_IDA!H19,J03_IDA!H19,J04_IDA!H19,J05_IDA!H19,J06_IDA!H19,J07_IDA!H19,J08_IDA!H19,J09_IDA!H19,J10_IDA!H19,J11_IDA!H19,J12_IDA!H19,J13_IDA!H19,J01_VTA!H19,J02_VTA!H19,J03_VTA!H19,J04_VTA!H19,J05_VTA!H19,J06_VTA!H19,J07_VTA!H19,J08_VTA!H19,J09_VTA!H19,J10_VTA!H19,J11_VTA!H19,J12_VTA!H19,J13_VTA!H19) -> 0 | I15: =SUM(J01_IDA!J19,J02_IDA!J19,J03_IDA!J19,J04_IDA!J19,J05_IDA!J19,J06_IDA!J19,J07_IDA!J19,J08_IDA!J19,J09_IDA!J19,J10_IDA!J19,J11_IDA!J19,J12_IDA!J19,J13_IDA!J19,J01_VTA!J19,J02_VTA!J19,J03_VTA!J19,J04_VTA!J19,J05_VTA!J19,J06_VTA!J19,J07_VTA!J19,J08_VTA!J19,J09_VTA!J19,J10_VTA!J19,J11_VTA!J19,J12_VTA!J19,J13_VTA!J19) -> 0 | J15: =SUM(J01_IDA!K19,J02_IDA!K19,J03_IDA!K19,J04_IDA!K19,J05_IDA!K19,J06_IDA!K19,J07_IDA!K19,J08_IDA!K19,J09_IDA!K19,J10_IDA!K19,J11_IDA!K19,J12_IDA!K19,J13_IDA!K19,J01_VTA!K19,J02_VTA!K19,J03_VTA!K19,J04_VTA!K19,J05_VTA!K19,J06_VTA!K19,J07_VTA!K19,J08_VTA!K19,J09_VTA!K19,J10_VTA!K19,J11_VTA!K19,J12_VTA!K19,J13_VTA!K19) -> 0 | K15: =SUM(J01_IDA!L19,J02_IDA!L19,J03_IDA!L19,J04_IDA!L19,J05_IDA!L19,J06_IDA!L19,J07_IDA!L19,J08_IDA!L19,J09_IDA!L19,J10_IDA!L19,J11_IDA!L19,J12_IDA!L19,J13_IDA!L19,J01_VTA!L19,J02_VTA!L19,J03_VTA!L19,J04_VTA!L19,J05_VTA!L19,J06_VTA!L19,J07_VTA!L19,J08_VTA!L19,J09_VTA!L19,J10_VTA!L19,J11_VTA!L19,J12_VTA!L19,J13_VTA!L19) -> 0 | L15: =SUM(--(J01_IDA!M19="SÍ"),--(J02_IDA!M19="SÍ"),--(J03_IDA!M19="SÍ"),--(J04_IDA!M19="SÍ"),--(J05_IDA!M19="SÍ"),--(J06_IDA!M19="SÍ"),--(J07_IDA!M19="SÍ"),--(J08_IDA!M19="SÍ"),--(J09_IDA!M19="SÍ"),--(J10_IDA!M19="SÍ"),--(J11_IDA!M19="SÍ"),--(J12_IDA!M19="SÍ"),--(J13_IDA!M19="SÍ"),--(J01_VTA!M19="SÍ"),--(J02_VTA!M19="SÍ"),--(J03_VTA!M19="SÍ"),--(J04_VTA!M19="SÍ"),--(J05_VTA!M19="SÍ"),--(J06_VTA!M19="SÍ"),--(J07_VTA!M19="SÍ"),--(J08_VTA!M19="SÍ"),--(J09_VTA!M19="SÍ"),--(J10_VTA!M19="SÍ"),--(J11_VTA!M19="SÍ"),--(J12_VTA!M19="SÍ"),--(J13_VTA!M19="SÍ")) -> 0 | M15: =SUM(J01_IDA!I19,J02_IDA!I19,J03_IDA!I19,J04_IDA!I19,J05_IDA!I19,J06_IDA!I19,J07_IDA!I19,J08_IDA!I19,J09_IDA!I19,J10_IDA!I19,J11_IDA!I19,J12_IDA!I19,J13_IDA!I19,J01_VTA!I19,J02_VTA!I19,J03_VTA!I19,J04_VTA!I19,J05_VTA!I19,J06_VTA!I19,J07_VTA!I19,J08_VTA!I19,J09_VTA!I19,J10_VTA!I19,J11_VTA!I19,J12_VTA!I19,J13_VTA!I19) -> 0
A16: 11 | B16: Mariana A. | C16: EXT. | D16: =SUM(--(J01_IDA!D20<>"NO CONVOCADA")*--(J01_IDA!D20<>""),--(J02_IDA!D20<>"NO CONVOCADA")*--(J02_IDA!D20<>""),--(J03_IDA!D20<>"NO CONVOCADA")*--(J03_IDA!D20<>""),--(J04_IDA!D20<>"NO CONVOCADA")*--(J04_IDA!D20<>""),--(J05_IDA!D20<>"NO CONVOCADA")*--(J05_IDA!D20<>""),--(J06_IDA!D20<>"NO CONVOCADA")*--(J06_IDA!D20<>""),--(J07_IDA!D20<>"NO CONVOCADA")*--(J07_IDA!D20<>""),--(J08_IDA!D20<>"NO CONVOCADA")*--(J08_IDA!D20<>""),--(J09_IDA!D20<>"NO CONVOCADA")*--(J09_IDA!D20<>""),--(J10_IDA!D20<>"NO CONVOCADA")*--(J10_IDA!D20<>""),--(J11_IDA!D20<>"NO CONVOCADA")*--(J11_IDA!D20<>""),--(J12_IDA!D20<>"NO CONVOCADA")*--(J12_IDA!D20<>""),--(J13_IDA!D20<>"NO CONVOCADA")*--(J13_IDA!D20<>""),--(J01_VTA!D20<>"NO CONVOCADA")*--(J01_VTA!D20<>""),--(J02_VTA!D20<>"NO CONVOCADA")*--(J02_VTA!D20<>""),--(J03_VTA!D20<>"NO CONVOCADA")*--(J03_VTA!D20<>""),--(J04_VTA!D20<>"NO CONVOCADA")*--(J04_VTA!D20<>""),--(J05_VTA!D20<>"NO CONVOCADA")*--(J05_VTA!D20<>""),--(J06_VTA!D20<>"NO CONVOCADA")*--(J06_VTA!D20<>""),--(J07_VTA!D20<>"NO CONVOCADA")*--(J07_VTA!D20<>""),--(J08_VTA!D20<>"NO CONVOCADA")*--(J08_VTA!D20<>""),--(J09_VTA!D20<>"NO CONVOCADA")*--(J09_VTA!D20<>""),--(J10_VTA!D20<>"NO CONVOCADA")*--(J10_VTA!D20<>""),--(J11_VTA!D20<>"NO CONVOCADA")*--(J11_VTA!D20<>""),--(J12_VTA!D20<>"NO CONVOCADA")*--(J12_VTA!D20<>""),--(J13_VTA!D20<>"NO CONVOCADA")*--(J13_VTA!D20<>"")) -> 1 | E16: =SUM(--(J01_IDA!D20="TITULAR"),--(J02_IDA!D20="TITULAR"),--(J03_IDA!D20="TITULAR"),--(J04_IDA!D20="TITULAR"),--(J05_IDA!D20="TITULAR"),--(J06_IDA!D20="TITULAR"),--(J07_IDA!D20="TITULAR"),--(J08_IDA!D20="TITULAR"),--(J09_IDA!D20="TITULAR"),--(J10_IDA!D20="TITULAR"),--(J11_IDA!D20="TITULAR"),--(J12_IDA!D20="TITULAR"),--(J13_IDA!D20="TITULAR"),--(J01_VTA!D20="TITULAR"),--(J02_VTA!D20="TITULAR"),--(J03_VTA!D20="TITULAR"),--(J04_VTA!D20="TITULAR"),--(J05_VTA!D20="TITULAR"),--(J06_VTA!D20="TITULAR"),--(J07_VTA!D20="TITULAR"),--(J08_VTA!D20="TITULAR"),--(J09_VTA!D20="TITULAR"),--(J10_VTA!D20="TITULAR"),--(J11_VTA!D20="TITULAR"),--(J12_VTA!D20="TITULAR"),--(J13_VTA!D20="TITULAR")) -> 1 | F16: =SUM(--(J01_IDA!D20="SUPLENTE"),--(J02_IDA!D20="SUPLENTE"),--(J03_IDA!D20="SUPLENTE"),--(J04_IDA!D20="SUPLENTE"),--(J05_IDA!D20="SUPLENTE"),--(J06_IDA!D20="SUPLENTE"),--(J07_IDA!D20="SUPLENTE"),--(J08_IDA!D20="SUPLENTE"),--(J09_IDA!D20="SUPLENTE"),--(J10_IDA!D20="SUPLENTE"),--(J11_IDA!D20="SUPLENTE"),--(J12_IDA!D20="SUPLENTE"),--(J13_IDA!D20="SUPLENTE"),--(J01_VTA!D20="SUPLENTE"),--(J02_VTA!D20="SUPLENTE"),--(J03_VTA!D20="SUPLENTE"),--(J04_VTA!D20="SUPLENTE"),--(J05_VTA!D20="SUPLENTE"),--(J06_VTA!D20="SUPLENTE"),--(J07_VTA!D20="SUPLENTE"),--(J08_VTA!D20="SUPLENTE"),--(J09_VTA!D20="SUPLENTE"),--(J10_VTA!D20="SUPLENTE"),--(J11_VTA!D20="SUPLENTE"),--(J12_VTA!D20="SUPLENTE"),--(J13_VTA!D20="SUPLENTE")) -> 0 | G16: =SUM(J01_IDA!G20,J02_IDA!G20,J03_IDA!G20,J04_IDA!G20,J05_IDA!G20,J06_IDA!G20,J07_IDA!G20,J08_IDA!G20,J09_IDA!G20,J10_IDA!G20,J11_IDA!G20,J12_IDA!G20,J13_IDA!G20,J01_VTA!G20,J02_VTA!G20,J03_VTA!G20,J04_VTA!G20,J05_VTA!G20,J06_VTA!G20,J07_VTA!G20,J08_VTA!G20,J09_VTA!G20,J10_VTA!G20,J11_VTA!G20,J12_VTA!G20,J13_VTA!G20) -> 75 | H16: =SUM(J01_IDA!H20,J02_IDA!H20,J03_IDA!H20,J04_IDA!H20,J05_IDA!H20,J06_IDA!H20,J07_IDA!H20,J08_IDA!H20,J09_IDA!H20,J10_IDA!H20,J11_IDA!H20,J12_IDA!H20,J13_IDA!H20,J01_VTA!H20,J02_VTA!H20,J03_VTA!H20,J04_VTA!H20,J05_VTA!H20,J06_VTA!H20,J07_VTA!H20,J08_VTA!H20,J09_VTA!H20,J10_VTA!H20,J11_VTA!H20,J12_VTA!H20,J13_VTA!H20) -> 0 | I16: =SUM(J01_IDA!J20,J02_IDA!J20,J03_IDA!J20,J04_IDA!J20,J05_IDA!J20,J06_IDA!J20,J07_IDA!J20,J08_IDA!J20,J09_IDA!J20,J10_IDA!J20,J11_IDA!J20,J12_IDA!J20,J13_IDA!J20,J01_VTA!J20,J02_VTA!J20,J03_VTA!J20,J04_VTA!J20,J05_VTA!J20,J06_VTA!J20,J07_VTA!J20,J08_VTA!J20,J09_VTA!J20,J10_VTA!J20,J11_VTA!J20,J12_VTA!J20,J13_VTA!J20) -> 1 | J16: =SUM(J01_IDA!K20,J02_IDA!K20,J03_IDA!K20,J04_IDA!K20,J05_IDA!K20,J06_IDA!K20,J07_IDA!K20,J08_IDA!K20,J09_IDA!K20,J10_IDA!K20,J11_IDA!K20,J12_IDA!K20,J13_IDA!K20,J01_VTA!K20,J02_VTA!K20,J03_VTA!K20,J04_VTA!K20,J05_VTA!K20,J06_VTA!K20,J07_VTA!K20,J08_VTA!K20,J09_VTA!K20,J10_VTA!K20,J11_VTA!K20,J12_VTA!K20,J13_VTA!K20) -> 0 | K16: =SUM(J01_IDA!L20,J02_IDA!L20,J03_IDA!L20,J04_IDA!L20,J05_IDA!L20,J06_IDA!L20,J07_IDA!L20,J08_IDA!L20,J09_IDA!L20,J10_IDA!L20,J11_IDA!L20,J12_IDA!L20,J13_IDA!L20,J01_VTA!L20,J02_VTA!L20,J03_VTA!L20,J04_VTA!L20,J05_VTA!L20,J06_VTA!L20,J07_VTA!L20,J08_VTA!L20,J09_VTA!L20,J10_VTA!L20,J11_VTA!L20,J12_VTA!L20,J13_VTA!L20) -> 0 | L16: =SUM(--(J01_IDA!M20="SÍ"),--(J02_IDA!M20="SÍ"),--(J03_IDA!M20="SÍ"),--(J04_IDA!M20="SÍ"),--(J05_IDA!M20="SÍ"),--(J06_IDA!M20="SÍ"),--(J07_IDA!M20="SÍ"),--(J08_IDA!M20="SÍ"),--(J09_IDA!M20="SÍ"),--(J10_IDA!M20="SÍ"),--(J11_IDA!M20="SÍ"),--(J12_IDA!M20="SÍ"),--(J13_IDA!M20="SÍ"),--(J01_VTA!M20="SÍ"),--(J02_VTA!M20="SÍ"),--(J03_VTA!M20="SÍ"),--(J04_VTA!M20="SÍ"),--(J05_VTA!M20="SÍ"),--(J06_VTA!M20="SÍ"),--(J07_VTA!M20="SÍ"),--(J08_VTA!M20="SÍ"),--(J09_VTA!M20="SÍ"),--(J10_VTA!M20="SÍ"),--(J11_VTA!M20="SÍ"),--(J12_VTA!M20="SÍ"),--(J13_VTA!M20="SÍ")) -> 0 | M16: =SUM(J01_IDA!I20,J02_IDA!I20,J03_IDA!I20,J04_IDA!I20,J05_IDA!I20,J06_IDA!I20,J07_IDA!I20,J08_IDA!I20,J09_IDA!I20,J10_IDA!I20,J11_IDA!I20,J12_IDA!I20,J13_IDA!I20,J01_VTA!I20,J02_VTA!I20,J03_VTA!I20,J04_VTA!I20,J05_VTA!I20,J06_VTA!I20,J07_VTA!I20,J08_VTA!I20,J09_VTA!I20,J10_VTA!I20,J11_VTA!I20,J12_VTA!I20,J13_VTA!I20) -> 0
